Workbook

Sheet Binder A - Equilibrium
A1: Background subtracted from Control IgG loaded biosensor
D2: Raw Data | H2: MW Normalized
D3: Raw Binding (nm) | H3: Normalized Binding (nm)
D4: Target X | E4: Target X/Partner Z complex | F4: Partner Z | H4: Target X | I4: Target X/Partner Z complex | J4: Partner Z | K4: Reference MW
C5: MW (g/mol) | D5: 18000 | E5: =D5+F5 -> 45000 | F5: 27000 | H5: =D$5 -> 18000 | I5: =E$5 -> 45000 | J5: =F$5 -> 27000 | K5: =I5 -> 45000
A6: [concentration] (M) | B6: [concentration] (nM) | C6: log | D6: Response at X = 295 s (nm) | H6: MW-normalized to Target X/Partner Z complex
A7: 1e-06 | B7: =A7*10^9 -> 1000 | C7: =LOG(A7) -> -6 | D7: 0.55043 | E7: 0.55049 | F7: 0.0019 | H7: =D7*($K$5/H$5) -> 1.376075 | I7: =E7*($K$5/I$5) -> 0.55049 | J7: =F7*($K$5/J$5) -> 0.0031666667
A8: 3.3333333e-07 | B8: =A8*10^9 -> 333.33333 | C8: =LOG(A8) -> -6.4771213 | D8: 0.54176 | E8: 0.54913 | F8: 0.00643 | H8: =D8*($K$5/H$5) -> 1.3544 | I8: =E8*($K$5/I$5) -> 0.54913 | J8: =F8*($K$5/J$5) -> 0.010716667
A9: 1.1111111e-07 | B9: =A9*10^9 -> 111.11111 | C9: =LOG(A9) -> -6.9542425 | D9: 0.52673 | E9: 0.54777 | F9: 0.00283 | H9: =D9*($K$5/H$5) -> 1.316825 | I9: =E9*($K$5/I$5) -> 0.54777 | J9: =F9*($K$5/J$5) -> 0.0047166667
A10: 3.7037037e-08 | B10: =A10*10^9 -> 37.037037 | C10: =LOG(A10) -> -7.4313638 | D10: 0.44285 | E10: 0.53141 | F10: 0.00342 | H10: =D10*($K$5/H$5) -> 1.107125 | I10: =E10*($K$5/I$5) -> 0.53141 | J10: =F10*($K$5/J$5) -> 0.0057
A11: 1.2345679e-08 | B11: =A11*10^9 -> 12.345679 | C11: =LOG(A11) -> -7.908485 | D11: 0.25083 | E11: 0.40635 | F11: 0.00152 | H11: =D11*($K$5/H$5) -> 0.627075 | I11: =E11*($K$5/I$5) -> 0.40635 | J11: =F11*($K$5/J$5) -> 0.0025333333
A12: 4.1152263e-09 | B12: =A12*10^9 -> 4.1152263 | C12: =LOG(A12) -> -8.3856063 | D12: 0.0988 | E12: 0.2012 | F12: 0.00442 | H12: =D12*($K$5/H$5) -> 0.247 | I12: =E12*($K$5/I$5) -> 0.2012 | J12: =F12*($K$5/J$5) -> 0.0073666667
A13: 1.3717421e-09 | B13: =A13*10^9 -> 1.3717421 | C13: =LOG(A13) -> -8.8627275 | D13: 0.0404 | E13: 0.07923 | F13: 0.0043 | H13: =D13*($K$5/H$5) -> 0.101 | I13: =E13*($K$5/I$5) -> 0.07923 | J13: =F13*($K$5/J$5) -> 0.0071666667
A14: 4.5724737e-10 | B14: =A14*10^9 -> 0.45724737 | C14: =LOG(A14) -> -9.3398488 | D14: 0.01113 | E14: 0.02621 | F14: 0.00291 | H14: =D14*($K$5/H$5) -> 0.027825 | I14: =E14*($K$5/I$5) -> 0.02621 | J14: =F14*($K$5/J$5) -> 0.00485
D16: Normalized to 100 | H16: MW Normalized to 100
D17: Normalized Binding (nm) | H17: Normalized Binding (nm)
D18: Target X | E18: Target X/Partner Z complex | F18: Partner Z | H18: Target X | I18: Target X/Partner Z complex | J18: Partner Z
C19: MW (g/mol) | D19: =D$5 -> 18000 | E19: =E$5 -> 45000 | F19: =F$5 -> 27000 | H19: =D$5 -> 18000 | I19: =E$5 -> 45000 | J19: =F$5 -> 27000
A20: [concentration] (M) | B20: [concentration] (nM) | C20: log
A21: =A7 -> 1e-06 | B21: =B7 -> 1000 | C21: =C7 -> -6 | D21: =D7/D$7*100 -> 100 | E21: =E7/E$7*100 -> 100 | F21: =F7/F$7*100 -> 100 | H21: =H7/H$7*100 -> 100 | I21: =I7/I$7*100 -> 100 | J21: =J7/J$7*100 -> 100
A22: =A8 -> 3.3333333e-07 | B22: =B8 -> 333.33333 | C22: =C8 -> -6.4771213 | D22: =D8/D$7*100 -> 98.424868 | E22: =E8/E$7*100 -> 99.752947 | F22: =F8/F$7*100 -> 338.42105 | H22: =H8/H$7*100 -> 98.424868 | I22: =I8/I$7*100 -> 99.752947 | J22: =J8/J$7*100 -> 338.42105
A23: =A9 -> 1.1111111e-07 | B23: =B9 -> 111.11111 | C23: =C9 -> -6.9542425 | D23: =D9/D$7*100 -> 95.694275 | E23: =E9/E$7*100 -> 99.505895 | F23: =F9/F$7*100 -> 148.94737 | H23: =H9/H$7*100 -> 95.694275 | I23: =I9/I$7*100 -> 99.505895 | J23: =J9/J$7*100 -> 148.94737
A24: =A10 -> 3.7037037e-08 | B24: =B10 -> 37.037037 | C24: =C10 -> -7.4313638 | D24: =D10/D$7*100 -> 80.45528 | E24: =E10/E$7*100 -> 96.533997 | F24: =F10/F$7*100 -> 180 | H24: =H10/H$7*100 -> 80.45528 | I24: =I10/I$7*100 -> 96.533997 | J24: =J10/J$7*100 -> 180
A25: =A11 -> 1.2345679e-08 | B25: =B11 -> 12.345679 | C25: =C11 -> -7.908485 | D25: =D11/D$7*100 -> 45.569827 | E25: =E11/E$7*100 -> 73.816055 | F25: =F11/F$7*100 -> 80 | H25: =H11/H$7*100 -> 45.569827 | I25: =I11/I$7*100 -> 73.816055 | J25: =J11/J$7*100 -> 80
A26: =A12 -> 4.1152263e-09 | B26: =B12 -> 4.1152263 | C26: =C12 -> -8.3856063 | D26: =D12/D$7*100 -> 17.949603 | E26: =E12/E$7*100 -> 36.549256 | F26: =F12/F$7*100 -> 232.63158 | H26: =H12/H$7*100 -> 17.949603 | I26: =I12/I$7*100 -> 36.549256 | J26: =J12/J$7*100 -> 232.63158
A27: =A13 -> 1.3717421e-09 | B27: =B13 -> 1.3717421 | C27: =C13 -> -8.8627275 | D27: =D13/D$7*100 -> 7.3397162 | E27: =E13/E$7*100 -> 14.392632 | F27: =F13/F$7*100 -> 226.31579 | H27: =H13/H$7*100 -> 7.3397162 | I27: =I13/I$7*100 -> 14.392632 | J27: =J13/J$7*100 -> 226.31579
A28: =A14 -> 4.5724737e-10 | B28: =B14 -> 0.45724737 | C28: =C14 -> -9.3398488 | D28: =D14/D$7*100 -> 2.0220555 | E28: =E14/E$7*100 -> 4.7612127 | F28: =F14/F$7*100 -> 153.15789 | H28: =H14/H$7*100 -> 2.0220555 | I28: =I14/I$7*100 -> 4.7612127 | J28: =J14/J$7*100 -> 153.15789

Sheet Binder B - Equilibrium
A1: Background subtracted from Control IgG loaded biosensor
D2: Raw Data | H2: MW Normalized
D3: Raw Binding (nm) | H3: Normalized Binding (nm)
D4: Target X | E4: Target X/Partner Z complex | F4: Partner Z | H4: Target X | I4: Target X/Partner Z complex | J4: Partner Z | K4: Reference MW
C5: MW (g/mol) | D5: 18000 | E5: =D5+F5 -> 45000 | F5: 27000 | H5: =D$5 -> 18000 | I5: =E$5 -> 45000 | J5: =F$5 -> 27000 | K5: =I5 -> 45000
A6: [concentration] (M) | B6: [concentration] (nM) | C6: log | D6: Response at X = 295 s (nm) | H6: MW-normalized to Target X/Partner Z complex
A7: 1e-06 | B7: =A7*10^9 -> 1000 | C7: =LOG(A7) -> -6 | D7: 0.52654 | E7: 0.53957 | F7: 0.18289 | H7: =D7*($K$5/H$5) -> 1.31635 | I7: =E7*($K$5/I$5) -> 0.53957 | J7: =F7*($K$5/J$5) -> 0.30481667
A8: 3.3333333e-07 | B8: =A8*10^9 -> 333.33333 | C8: =LOG(A8) -> -6.4771213 | D8: 0.47935 | E8: 0.51985 | F8: 0.07993 | H8: =D8*($K$5/H$5) -> 1.198375 | I8: =E8*($K$5/I$5) -> 0.51985 | J8: =F8*($K$5/J$5) -> 0.13321667
A9: 1.1111111e-07 | B9: =A9*10^9 -> 111.11111 | C9: =LOG(A9) -> -6.9542425 | D9: 0.37812 | E9: 0.46307 | F9: 0.0269 | H9: =D9*($K$5/H$5) -> 0.9453 | I9: =E9*($K$5/I$5) -> 0.46307 | J9: =F9*($K$5/J$5) -> 0.044833333
A10: 3.7037037e-08 | B10: =A10*10^9 -> 37.037037 | C10: =LOG(A10) -> -7.4313638 | D10: 0.21421 | E10: 0.3444 | F10: 0.00753 | H10: =D10*($K$5/H$5) -> 0.535525 | I10: =E10*($K$5/I$5) -> 0.3444 | J10: =F10*($K$5/J$5) -> 0.01255
A11: 1.2345679e-08 | B11: =A11*10^9 -> 12.345679 | C11: =LOG(A11) -> -7.908485 | D11: 0.09148 | E11: 0.17936 | F11: 0.00421 | H11: =D11*($K$5/H$5) -> 0.2287 | I11: =E11*($K$5/I$5) -> 0.17936 | J11: =F11*($K$5/J$5) -> 0.0070166667
A12: 4.1152263e-09 | B12: =A12*10^9 -> 4.1152263 | C12: =LOG(A12) -> -8.3856063 | D12: 0.0354 | E12: 0.07148 | F12: -0.00173 | H12: =D12*($K$5/H$5) -> 0.0885 | I12: =E12*($K$5/I$5) -> 0.07148 | J12: =F12*($K$5/J$5) -> -0.0028833333
A13: 1.3717421e-09 | B13: =A13*10^9 -> 1.3717421 | C13: =LOG(A13) -> -8.8627275 | D13: 0.01328 | E13: 0.02503 | F13: 0.0001 | H13: =D13*($K$5/H$5) -> 0.0332 | I13: =E13*($K$5/I$5) -> 0.02503 | J13: =F13*($K$5/J$5) -> 0.00016666667
A14: 4.5724737e-10 | B14: =A14*10^9 -> 0.45724737 | C14: =LOG(A14) -> -9.3398488 | D14: 0.00094 | E14: 0.01036 | F14: 0.00051 | H14: =D14*($K$5/H$5) -> 0.00235 | I14: =E14*($K$5/I$5) -> 0.01036 | J14: =F14*($K$5/J$5) -> 0.00085
D16: Normalized to 100 | H16: MW Normalized to 100
D17: Normalized Binding (nm) | H17: Normalized Binding (nm)
D18: Target X | E18: Target X/Partner Z complex | F18: Partner Z | H18: Target X | I18: Target X/Partner Z complex | J18: Partner Z
C19: MW (g/mol) | D19: =D$5 -> 18000 | E19: =E$5 -> 45000 | F19: =F$5 -> 27000 | H19: =D$5 -> 18000 | I19: =E$5 -> 45000 | J19: =F$5 -> 27000
A20: [concentration] (M) | B20: [concentration] (nM) | C20: log
A21: =A7 -> 1e-06 | B21: =B7 -> 1000 | C21: =C7 -> -6 | D21: =D7/D$7*100 -> 100 | E21: =E7/E$7*100 -> 100 | F21: =F7/F$7*100 -> 100 | H21: =H7/H$7*100 -> 100 | I21: =I7/I$7*100 -> 100 | J21: =J7/J$7*100 -> 100
A22: =A8 -> 3.3333333e-07 | B22: =B8 -> 333.33333 | C22: =C8 -> -6.4771213 | D22: =D8/D$7*100 -> 91.037718 | E22: =E8/E$7*100 -> 96.345238 | F22: =F8/F$7*100 -> 43.703866 | H22: =H8/H$7*100 -> 91.037718 | I22: =I8/I$7*100 -> 96.345238 | J22: =J8/J$7*100 -> 43.703866
A23: =A9 -> 1.1111111e-07 | B23: =B9 -> 111.11111 | C23: =C9 -> -6.9542425 | D23: =D9/D$7*100 -> 71.812208 | E23: =E9/E$7*100 -> 85.822043 | F23: =F9/F$7*100 -> 14.708295 | H23: =H9/H$7*100 -> 71.812208 | I23: =I9/I$7*100 -> 85.822043 | J23: =J9/J$7*100 -> 14.708295
A24: =A10 -> 3.7037037e-08 | B24: =B10 -> 37.037037 | C24: =C10 -> -7.4313638 | D24: =D10/D$7*100 -> 40.682569 | E24: =E10/E$7*100 -> 63.828604 | F24: =F10/F$7*100 -> 4.1172289 | H24: =H10/H$7*100 -> 40.682569 | I24: =I10/I$7*100 -> 63.828604 | J24: =J10/J$7*100 -> 4.1172289
A25: =A11 -> 1.2345679e-08 | B25: =B11 -> 12.345679 | C25: =C11 -> -7.908485 | D25: =D11/D$7*100 -> 17.373799 | E25: =E11/E$7*100 -> 33.241285 | F25: =F11/F$7*100 -> 2.3019301 | H25: =H11/H$7*100 -> 17.373799 | I25: =I11/I$7*100 -> 33.241285 | J25: =J11/J$7*100 -> 2.3019301
A26: =A12 -> 4.1152263e-09 | B26: =B12 -> 4.1152263 | C26: =C12 -> -8.3856063 | D26: =D12/D$7*100 -> 6.7231359 | E26: =E12/E$7*100 -> 13.247586 | F26: =F12/F$7*100 -> -0.94592378 | H26: =H12/H$7*100 -> 6.7231359 | I26: =I12/I$7*100 -> 13.247586 | J26: =J12/J$7*100 -> -0.94592378
A27: =A13 -> 1.3717421e-09 | B27: =B13 -> 1.3717421 | C27: =C13 -> -8.8627275 | D27: =D13/D$7*100 -> 2.5221256 | E27: =E13/E$7*100 -> 4.6388791 | F27: =F13/F$7*100 -> 0.054677675 | H27: =H13/H$7*100 -> 2.5221256 | I27: =I13/I$7*100 -> 4.6388791 | J27: =J13/J$7*100 -> 0.054677675
A28: =A14 -> 4.5724737e-10 | B28: =B14 -> 0.45724737 | C28: =C14 -> -9.3398488 | D28: =D14/D$7*100 -> 0.17852395 | E28: =E14/E$7*100 -> 1.9200474 | F28: =F14/F$7*100 -> 0.27885614 | H28: =H14/H$7*100 -> 0.17852395 | I28: =I14/I$7*100 -> 1.9200474 | J28: =J14/J$7*100 -> 0.27885614

Sheet Kinetic KDs
A1: Kinetic KDs
A2: Fit rows used: Full X² < 3, Full R² > 0.9, and KD, kon and kdis all determinate (not censored or non-converged). Only the KD column is used; the 2:1 second-site KD2 is ignored.
A3: Flagged = used, but KD is more than 5-fold from the median of the group's used rows; flagged rows stay included. Change a row's Include to No in the table below and the summary recalculates.
A5: Summary
A6: Ligand | B6: Analyte | C6: Rows used | D6: Rows flagged | E6: Mean kon (1/Ms) | F6: Mean kdis (1/s) | G6: KD from mean kdis / mean kon (nM) | H6: Mean of per-row KDs (nM) | I6: Ratio of the two KDs | J6: Agreement | K6: Mean KD excl. flagged rows (nM) | L6: Notes
A7: Binder A | B7: Target X | C7: =COUNTIFS($A$18:$A$65,$A7,$B$18:$B$65,$B7,$D$18:$D$65,"Yes") -> 7 | D7: =COUNTIFS($A$18:$A$65,$A7,$B$18:$B$65,$B7,$D$18:$D$65,"Yes",$K$18:$K$65,"Yes") -> 0 | E7: =IFERROR(AVERAGEIFS($F$18:$F$65,$A$18:$A$65,$A7,$B$18:$B$65,$B7,$D$18:$D$65,"Yes"),"n/a") -> 214857.14 | F7: =IFERROR(AVERAGEIFS($G$18:$G$65,$A$18:$A$65,$A7,$B$18:$B$65,$B7,$D$18:$D$65,"Yes"),"n/a") -> 0.000994 | G7: =IFERROR(F7/E7*10^9,"n/a") -> 4.6263298 | H7: =IFERROR(AVERAGEIFS($E$18:$E$65,$A$18:$A$65,$A7,$B$18:$B$65,$B7,$D$18:$D$65,"Yes"),"n/a") -> 4.7071429 | I7: =IFERROR(MAX(G7,H7)/MIN(G7,H7),"n/a") -> 1.0174681 | J7: =IF(ISNUMBER(I7),IF(I7>2,"differ","agree"),"") -> agree | K7: =IFERROR(AVERAGEIFS($E$18:$E$65,$A$18:$A$65,$A7,$B$18:$B$65,$B7,$D$18:$D$65,"Yes",$K$18:$K$65,"<>Yes"),"n/a") -> 4.7071429
A8: Binder A | B8: Target X/Partner Z complex | C8: =COUNTIFS($A$18:$A$65,$A8,$B$18:$B$65,$B8,$D$18:$D$65,"Yes") -> 8 | D8: =COUNTIFS($A$18:$A$65,$A8,$B$18:$B$65,$B8,$D$18:$D$65,"Yes",$K$18:$K$65,"Yes") -> 0 | E8: =IFERROR(AVERAGEIFS($F$18:$F$65,$A$18:$A$65,$A8,$B$18:$B$65,$B8,$D$18:$D$65,"Yes"),"n/a") -> 431125 | F8: =IFERROR(AVERAGEIFS($G$18:$G$65,$A$18:$A$65,$A8,$B$18:$B$65,$B8,$D$18:$D$65,"Yes"),"n/a") -> 0.000395875 | G8: =IFERROR(F8/E8*10^9,"n/a") -> 0.91823717 | H8: =IFERROR(AVERAGEIFS($E$18:$E$65,$A$18:$A$65,$A8,$B$18:$B$65,$B8,$D$18:$D$65,"Yes"),"n/a") -> 0.948375 | I8: =IFERROR(MAX(G8,H8)/MIN(G8,H8),"n/a") -> 1.0328214 | J8: =IF(ISNUMBER(I8),IF(I8>2,"differ","agree"),"") -> agree | K8: =IFERROR(AVERAGEIFS($E$18:$E$65,$A$18:$A$65,$A8,$B$18:$B$65,$B8,$D$18:$D$65,"Yes",$K$18:$K$65,"<>Yes"),"n/a") -> 0.948375
A9: Binder A | B9: Partner Z | C9: =COUNTIFS($A$18:$A$65,$A9,$B$18:$B$65,$B9,$D$18:$D$65,"Yes") -> 0 | D9: =COUNTIFS($A$18:$A$65,$A9,$B$18:$B$65,$B9,$D$18:$D$65,"Yes",$K$18:$K$65,"Yes") -> 0 | E9: =IFERROR(AVERAGEIFS($F$18:$F$65,$A$18:$A$65,$A9,$B$18:$B$65,$B9,$D$18:$D$65,"Yes"),"n/a") -> n/a | F9: =IFERROR(AVERAGEIFS($G$18:$G$65,$A$18:$A$65,$A9,$B$18:$B$65,$B9,$D$18:$D$65,"Yes"),"n/a") -> n/a | G9: =IFERROR(F9/E9*10^9,"n/a") -> n/a | H9: =IFERROR(AVERAGEIFS($E$18:$E$65,$A$18:$A$65,$A9,$B$18:$B$65,$B9,$D$18:$D$65,"Yes"),"n/a") -> n/a | I9: =IFERROR(MAX(G9,H9)/MIN(G9,H9),"n/a") -> n/a | J9: =IF(ISNUMBER(I9),IF(I9>2,"differ","agree"),"") | K9: =IFERROR(AVERAGEIFS($E$18:$E$65,$A$18:$A$65,$A9,$B$18:$B$65,$B9,$D$18:$D$65,"Yes",$K$18:$K$65,"<>Yes"),"n/a") -> n/a | L9: No fit row passed the filters.
A10: Binder B | B10: Target X | C10: =COUNTIFS($A$18:$A$65,$A10,$B$18:$B$65,$B10,$D$18:$D$65,"Yes") -> 6 | D10: =COUNTIFS($A$18:$A$65,$A10,$B$18:$B$65,$B10,$D$18:$D$65,"Yes",$K$18:$K$65,"Yes") -> 0 | E10: =IFERROR(AVERAGEIFS($F$18:$F$65,$A$18:$A$65,$A10,$B$18:$B$65,$B10,$D$18:$D$65,"Yes"),"n/a") -> 102366.67 | F10: =IFERROR(AVERAGEIFS($G$18:$G$65,$A$18:$A$65,$A10,$B$18:$B$65,$B10,$D$18:$D$65,"Yes"),"n/a") -> 0.0050116667 | G10: =IFERROR(F10/E10*10^9,"n/a") -> 48.957994 | H10: =IFERROR(AVERAGEIFS($E$18:$E$65,$A$18:$A$65,$A10,$B$18:$B$65,$B10,$D$18:$D$65,"Yes"),"n/a") -> 48.966667 | I10: =IFERROR(MAX(G10,H10)/MIN(G10,H10),"n/a") -> 1.0001771 | J10: =IF(ISNUMBER(I10),IF(I10>2,"differ","agree"),"") -> agree | K10: =IFERROR(AVERAGEIFS($E$18:$E$65,$A$18:$A$65,$A10,$B$18:$B$65,$B10,$D$18:$D$65,"Yes",$K$18:$K$65,"<>Yes"),"n/a") -> 48.966667
A11: Binder B | B11: Target X/Partner Z complex | C11: =COUNTIFS($A$18:$A$65,$A11,$B$18:$B$65,$B11,$D$18:$D$65,"Yes") -> 6 | D11: =COUNTIFS($A$18:$A$65,$A11,$B$18:$B$65,$B11,$D$18:$D$65,"Yes",$K$18:$K$65,"Yes") -> 0 | E11: =IFERROR(AVERAGEIFS($F$18:$F$65,$A$18:$A$65,$A11,$B$18:$B$65,$B11,$D$18:$D$65,"Yes"),"n/a") -> 201833.33 | F11: =IFERROR(AVERAGEIFS($G$18:$G$65,$A$18:$A$65,$A11,$B$18:$B$65,$B11,$D$18:$D$65,"Yes"),"n/a") -> 0.0039983333 | G11: =IFERROR(F11/E11*10^9,"n/a") -> 19.810074 | H11: =IFERROR(AVERAGEIFS($E$18:$E$65,$A$18:$A$65,$A11,$B$18:$B$65,$B11,$D$18:$D$65,"Yes"),"n/a") -> 19.8 | I11: =IFERROR(MAX(G11,H11)/MIN(G11,H11),"n/a") -> 1.0005088 | J11: =IF(ISNUMBER(I11),IF(I11>2,"differ","agree"),"") -> agree | K11: =IFERROR(AVERAGEIFS($E$18:$E$65,$A$18:$A$65,$A11,$B$18:$B$65,$B11,$D$18:$D$65,"Yes",$K$18:$K$65,"<>Yes"),"n/a") -> 19.8
A12: Binder B | B12: Partner Z | C12: =COUNTIFS($A$18:$A$65,$A12,$B$18:$B$65,$B12,$D$18:$D$65,"Yes") -> 3 | D12: =COUNTIFS($A$18:$A$65,$A12,$B$18:$B$65,$B12,$D$18:$D$65,"Yes",$K$18:$K$65,"Yes") -> 0 | E12: =IFERROR(AVERAGEIFS($F$18:$F$65,$A$18:$A$65,$A12,$B$18:$B$65,$B12,$D$18:$D$65,"Yes"),"n/a") -> 21700 | F12: =IFERROR(AVERAGEIFS($G$18:$G$65,$A$18:$A$65,$A12,$B$18:$B$65,$B12,$D$18:$D$65,"Yes"),"n/a") -> 0.040333333 | G12: =IFERROR(F12/E12*10^9,"n/a") -> 1858.679 | H12: =IFERROR(AVERAGEIFS($E$18:$E$65,$A$18:$A$65,$A12,$B$18:$B$65,$B12,$D$18:$D$65,"Yes"),"n/a") -> 1880 | I12: =IFERROR(MAX(G12,H12)/MIN(G12,H12),"n/a") -> 1.0114711 | J12: =IF(ISNUMBER(I12),IF(I12>2,"differ","agree"),"") -> agree | K12: =IFERROR(AVERAGEIFS($E$18:$E$65,$A$18:$A$65,$A12,$B$18:$B$65,$B12,$D$18:$D$65,"Yes",$K$18:$K$65,"<>Yes"),"n/a") -> 1880
A13: Ratio = larger / smaller of the two KD estimates; 'differ' when above 2. 'n/a' = no included rows.
A16: Fit rows
A17: Ligand | B17: Analyte | C17: Conc (nM) | D17: Include | E17: KD (nM) | F17: kon (1/Ms) | G17: kdis (1/s) | H17: Full X² | I17: Full R² | J17: Note | K17: Flagged
A18: Binder A | B18: Target X | C18: 1000 | D18: Yes | E18: 5.02 | F18: 200000 | G18: 0.001 | H18: 0.004602 | I18: 0.998811
A19: Binder A | B19: Target X | C19: 333.333 | D19: Yes | E19: 4.99 | F19: 200000 | G19: 0.000999 | H19: 0.004885 | I19: 0.999139
A20: Binder A | B20: Target X | C20: 111.111 | D20: Yes | E20: 5 | F20: 200000 | G20: 0.001 | H20: 0.004917 | I20: 0.999485
A21: Binder A | B21: Target X | C21: 37.037 | D21: Yes | E21: 4.99 | F21: 200000 | G21: 0.000999 | H21: 0.004426 | I21: 0.999616
A22: Binder A | B22: Target X | C22: 12.3457 | D22: Yes | E22: 4.92 | F22: 202000 | G22: 0.000993 | H22: 0.004793 | I22: 0.999018
A23: Binder A | B23: Target X | C23: 4.11523 | D23: Yes | E23: 4.64 | F23: 211000 | G23: 0.000978 | H23: 0.00507 | I23: 0.994486
A24: Binder A | B24: Target X | C24: 1.37174 | D24: Yes | E24: 3.39 | F24: 291000 | G24: 0.000989 | H24: 0.005016 | I24: 0.959744
A25: Binder A | B25: Target X | C25: 0.457247 | D25: No | E25: <1.0E-12 M | F25: <1.0E-12 | G25: <1.0E-07 | H25: 9.99 | I25: 0 | J25: Full X² 9.99 is not < 3
A26: Binder A | B26: Target X/Partner Z complex | C26: 1000 | D26: Yes | E26: 0.998 | F26: 400000 | G26: 0.000399 | H26: 0.004956 | I26: 0.996202
A27: Binder A | B27: Target X/Partner Z complex | C27: 333.333 | D27: Yes | E27: 0.991 | F27: 401000 | G27: 0.000398 | H27: 0.005079 | I27: 0.998013
A28: Binder A | B28: Target X/Partner Z complex | C28: 111.111 | D28: Yes | E28: 1 | F28: 399000 | G28: 0.0004 | H28: 0.004904 | I28: 0.999183
A29: Binder A | B29: Target X/Partner Z complex | C29: 37.037 | D29: Yes | E29: 0.997 | F29: 400000 | G29: 0.000399 | H29: 0.004981 | I29: 0.999617
A30: Binder A | B30: Target X/Partner Z complex | C30: 12.3457 | D30: Yes | E30: 1.01 | F30: 398000 | G30: 0.000402 | H30: 0.004811 | I30: 0.999629
A31: Binder A | B31: Target X/Partner Z complex | C31: 4.11523 | D31: Yes | E31: 1.01 | F31: 399000 | G31: 0.000401 | H31: 0.004887 | I31: 0.998774
A32: Binder A | B32: Target X/Partner Z complex | C32: 1.37174 | D32: Yes | E32: 1.03 | F32: 394000 | G32: 0.000406 | H32: 0.004831 | I32: 0.992552
A33: Binder A | B33: Target X/Partner Z complex | C33: 0.457247 | D33: Yes | E33: 0.551 | F33: 658000 | G33: 0.000362 | H33: 0.004975 | I33: 0.943432
A34: Binder A | B34: Partner Z | C34: 1000 | D34: No | E34: <1.0E-12 M | F34: <1.0E-12 | G34: <1.0E-07 | H34: 9.99 | I34: 0 | J34: Full X² 9.99 is not < 3
A35: Binder A | B35: Partner Z | C35: 333.333 | D35: No | E35: <1.0E-12 M | F35: <1.0E-12 | G35: <1.0E-07 | H35: 9.99 | I35: 0 | J35: Full X² 9.99 is not < 3
A36: Binder A | B36: Partner Z | C36: 111.111 | D36: No | E36: <1.0E-12 M | F36: <1.0E-12 | G36: <1.0E-07 | H36: 9.99 | I36: 0 | J36: Full X² 9.99 is not < 3
A37: Binder A | B37: Partner Z | C37: 37.037 | D37: No | E37: <1.0E-12 M | F37: <1.0E-12 | G37: <1.0E-07 | H37: 9.99 | I37: 0 | J37: Full X² 9.99 is not < 3
A38: Binder A | B38: Partner Z | C38: 12.3457 | D38: No | E38: <1.0E-12 M | F38: <1.0E-12 | G38: <1.0E-07 | H38: 9.99 | I38: 0 | J38: Full X² 9.99 is not < 3
A39: Binder A | B39: Partner Z | C39: 4.11523 | D39: No | E39: <1.0E-12 M | F39: <1.0E-12 | G39: <1.0E-07 | H39: 9.99 | I39: 0 | J39: Full X² 9.99 is not < 3
A40: Binder A | B40: Partner Z | C40: 1.37174 | D40: No | E40: <1.0E-12 M | F40: <1.0E-12 | G40: <1.0E-07 | H40: 9.99 | I40: 0 | J40: Full X² 9.99 is not < 3
A41: Binder A | B41: Partner Z | C41: 0.457247 | D41: No | E41: <1.0E-12 M | F41: <1.0E-12 | G41: <1.0E-07 | H41: 9.99 | I41: 0 | J41: Full X² 9.99 is not < 3
A42: Binder B | B42: Target X | C42: 1000 | D42: Yes | E42: 50.1 | F42: 99700 | G42: 0.005 | H42: 0.004632 | I42: 0.99983
A43: Binder B | B43: Target X | C43: 333.333 | D43: Yes | E43: 50 | F43: 99900 | G43: 0.005 | H43: 0.005071 | I43: 0.999773
...

Sheet KD summary
A1: KD summary (nM)
A2: Equilibrium KD = EC50 of the sigmoidal equilibrium fit (the fit the Prism analyses apply), converted from log10 M to nM. Kinetic KD = mean of the per-row KDs on the Kinetic KDs tab (included rows only).
A3: The equilibrium value is calculated here with the same model Prism uses, not read from Prism's own results table; check it against the Prism analysis. Intervals are approximate (asymptotic, Prism reports profile-likelihood).
A5: Ligand | B5: Analyte | C5: Equilibrium KD (nM) | D5: 95% CI low (nM) | E5: 95% CI high (nM) | F5: Fit R² | G5: Mean per-row kinetic KD (nM) | H5: Kinetic rows used | I5: Equilibrium notes
A6: Binder A | B6: Target X | C6: 13.489723 | D6: 9.1217537 | E6: 19.949301 | F6: 0.99454334 | G6: ='Kinetic KDs'!H7 -> 4.7071429 | H6: ='Kinetic KDs'!C7 -> 7
A7: Binder A | B7: Target X/Partner Z complex | C7: 5.3158671 | D7: 3.1869947 | E7: 8.8667993 | F7: 0.99103415 | G7: ='Kinetic KDs'!H8 -> 0.948375 | H7: ='Kinetic KDs'!C8 -> 8
A8: Binder A | B8: Partner Z | C8: 0.00011994235 | D8: 0 | E8: n/a | F8: 0.0040750545 | G8: ='Kinetic KDs'!H9 -> n/a | H8: ='Kinetic KDs'!C9 -> 0 | I8: R² = 0.004 is below 0.95; EC50 lies outside the tested concentration range; LogEC50 95% interval spans 155389.26 log units (approximate)
A9: Binder B | B9: Target X | C9: 56.839277 | D9: 50.643889 | E9: 63.792562 | F9: 0.99952934 | G9: ='Kinetic KDs'!H10 -> 48.966667 | H9: ='Kinetic KDs'!C10 -> 6
A10: Binder B | B10: Target X/Partner Z complex | C10: 23.729806 | D10: 20.822554 | E10: 27.04297 | F10: 0.99938639 | G10: ='Kinetic KDs'!H11 -> 19.8 | H10: ='Kinetic KDs'!C11 -> 6
A11: Binder B | B11: Partner Z | C11: 1878.9155 | D11: 1377.9735 | E11: 2561.9677 | F11: 0.99945519 | G11: ='Kinetic KDs'!H12 -> 1880 | H11: ='Kinetic KDs'!C12 -> 3 | I11: top concentration is only 0.5× EC50: the top plateau is not reached, so Top and EC50 are extrapolated; EC50 lies outside the tested concentration range; fitted Top (0.529) is more than twice the highest response (0.183)
