Workbook
Name ProteinNames: Proteins!$A$5:$A$40

Sheet bli2prism
A1: bli2prism analysis setup
A2: Yellow cells are inputs. Contents and MWs are read from the Setup sheet, so edit the plate map and protein table there.
A4: [Experiment]
A5: Experiment name | B5: Demo binding experiment | C5: Free text.
A6: Results CSV | B6: kineticanalysistableresults.csv | C6: File name of the Octet kinetic analysis results table.
A7: Prism template | C7: Optional. File name of a populated .prism whose graphs are kept (template route). Leave blank to build without a template.
A8: Prism output file | B8: Demo binding experiment | C8: Name of the .prism to produce. Upload an EMPTY Prism project with exactly this name into the run folder and the tool fills it in; the result is written to rebuild/<name>, so your upload is never overwritten.
A9: Kinetic concentrations per ligand | B9: 8 | C9: REQUIRED, entered by hand: how many dilution steps (A, B, ...) get a kinetics sheet.
A10: Number of analytes | B10: 3 | C10: REQUIRED, entered by hand (1-7): how many analytes are in the plate map and the raw files. Must equal the number of plate columns whose Role is Analyte. (Detected 3 Analyte column(s) in the plate map.)
A11: Normalization reference analyte | B11: Analyte Z | C11: Name of the analyte whose MW everything is normalized to (as written in the plate map).
A12: Dilution start (M) | B12: =Setup!N5 -> 1e-06 | C12: From the Setup sheet.
A13: Dilution factor | B13: =Setup!R5 -> 3 | C13: From the Setup sheet.
A14: Dilution steps | B14: 8 | C14: Concentrations in the series (A..H = 8).
A16: [Plate columns] | C16: Columns A, B, I, J are formulas that list every entry of the Setup plate map: edit the plate map, not these. Role, Display name and Made of are yours to fill in; if you reorder the plate map, re-check them, they do not move with the names. | L16: [Plate map scan] helper formulas, leave alone
A17: Plate column | B17: Contents (from Setup) | C17: Role | D17: Display name | E17: Made of (protein 1) | F17: Made of (protein 2) | G17: MW (g/mol) | H17: Check | I17: Plate rows | J17: Label (shown on Setup) | K17: Sensor rows (count) | L17: Plate column | M17: Row | N17: Name | O17: Starts entry | P17: Entry # | Q17: Next entry at row
A18: =IFERROR(INDEX($L$18:$L$113,MATCH(1,$P$18:$P$113,0)),"") -> 1 | B18: =IFERROR(INDEX($N$18:$N$113,MATCH(1,$P$18:$P$113,0)),"") -> Buffer | C18: Buffer | G18: =IF(OR(C18="Ligand",C18="Reference",C18="Analyte"),IF(E18="",0,SUMIF(Proteins!$A$5:$A$40,E18,Proteins!$C$5:$C$40))+IF(F18="",0,SUMIF(Proteins!$A$5:$A$40,F18,Proteins!$C$5:$C$40)),"") | I18: =IFERROR(IF(INDEX($Q$18:$Q$113,MATCH(1,$P$18:$P$113,0))-1=INDEX($M$18:$M$113,MATCH(1,$P$18:$P$113,0)),MID("ABCDEFGH",INDEX($M$18:$M$113,MATCH(1,$P$18:$P$113,0)),1),MID("ABCDEFGH",INDEX($M$18:$M$113,MATCH(1,$P$18:$P$113,0)),1)&"-"&MID("ABCDEFGH",INDEX($Q$18:$Q$113,MATCH(1,$P$18:$P$113,0))-1,1)),"") -> A-H | J18: =IF(C18="","",IF(OR(C18="Ligand",C18="Analyte"),C18&" "&COUNTIFS($C$18:C18,C18),C18)) -> Buffer | K18: =IFERROR(INDEX($Q$18:$Q$113,MATCH(1,$P$18:$P$113,0))-INDEX($M$18:$M$113,MATCH(1,$P$18:$P$113,0)),"") -> 8 | L18: 1 | M18: 1 | N18: =IF(Setup!B5="","",Setup!B5) -> Buffer | O18: =IF(N18="",0,1) -> 1 | P18: =O18 -> 1 | Q18: =IF(L19<>L18,9,IF(O19=1,M19,Q19)) -> 9
A19: =IFERROR(INDEX($L$18:$L$113,MATCH(2,$P$18:$P$113,0)),"") -> 2 | B19: =IFERROR(INDEX($N$18:$N$113,MATCH(2,$P$18:$P$113,0)),"") -> Binder A | C19: Ligand | E19: Binder A | G19: =IF(OR(C19="Ligand",C19="Reference",C19="Analyte"),IF(E19="",0,SUMIF(Proteins!$A$5:$A$40,E19,Proteins!$C$5:$C$40))+IF(F19="",0,SUMIF(Proteins!$A$5:$A$40,F19,Proteins!$C$5:$C$40)),"") -> 145000 | I19: =IFERROR(IF(INDEX($Q$18:$Q$113,MATCH(2,$P$18:$P$113,0))-1=INDEX($M$18:$M$113,MATCH(2,$P$18:$P$113,0)),MID("ABCDEFGH",INDEX($M$18:$M$113,MATCH(2,$P$18:$P$113,0)),1),MID("ABCDEFGH",INDEX($M$18:$M$113,MATCH(2,$P$18:$P$113,0)),1)&"-"&MID("ABCDEFGH",INDEX($Q$18:$Q$113,MATCH(2,$P$18:$P$113,0))-1,1)),"") -> A-H | J19: =IF(C19="","",IF(OR(C19="Ligand",C19="Analyte"),C19&" "&COUNTIFS($C$18:C19,C19),C19)) -> Ligand 1 | K19: =IFERROR(INDEX($Q$18:$Q$113,MATCH(2,$P$18:$P$113,0))-INDEX($M$18:$M$113,MATCH(2,$P$18:$P$113,0)),"") -> 8 | L19: 1 | M19: 2 | N19: =IF(Setup!B6="","",Setup!B6) -> Buffer | O19: =IF(N19="",0,IF(AND(L19=L18,N19=N18),0,1)) -> 0 | P19: =P18+O19 -> 1 | Q19: =IF(L20<>L19,9,IF(O20=1,M20,Q20)) -> 9
A20: =IFERROR(INDEX($L$18:$L$113,MATCH(3,$P$18:$P$113,0)),"") -> 3 | B20: =IFERROR(INDEX($N$18:$N$113,MATCH(3,$P$18:$P$113,0)),"") -> Binder B | C20: Ligand | E20: Binder B | G20: =IF(OR(C20="Ligand",C20="Reference",C20="Analyte"),IF(E20="",0,SUMIF(Proteins!$A$5:$A$40,E20,Proteins!$C$5:$C$40))+IF(F20="",0,SUMIF(Proteins!$A$5:$A$40,F20,Proteins!$C$5:$C$40)),"") -> 148000 | I20: =IFERROR(IF(INDEX($Q$18:$Q$113,MATCH(3,$P$18:$P$113,0))-1=INDEX($M$18:$M$113,MATCH(3,$P$18:$P$113,0)),MID("ABCDEFGH",INDEX($M$18:$M$113,MATCH(3,$P$18:$P$113,0)),1),MID("ABCDEFGH",INDEX($M$18:$M$113,MATCH(3,$P$18:$P$113,0)),1)&"-"&MID("ABCDEFGH",INDEX($Q$18:$Q$113,MATCH(3,$P$18:$P$113,0))-1,1)),"") -> A-H | J20: =IF(C20="","",IF(OR(C20="Ligand",C20="Analyte"),C20&" "&COUNTIFS($C$18:C20,C20),C20)) -> Ligand 2 | K20: =IFERROR(INDEX($Q$18:$Q$113,MATCH(3,$P$18:$P$113,0))-INDEX($M$18:$M$113,MATCH(3,$P$18:$P$113,0)),"") -> 8 | L20: 1 | M20: 3 | N20: =IF(Setup!B7="","",Setup!B7) -> Buffer | O20: =IF(N20="",0,IF(AND(L20=L19,N20=N19),0,1)) -> 0 | P20: =P19+O20 -> 1 | Q20: =IF(L21<>L20,9,IF(O21=1,M21,Q21)) -> 9
A21: =IFERROR(INDEX($L$18:$L$113,MATCH(4,$P$18:$P$113,0)),"") -> 4 | B21: =IFERROR(INDEX($N$18:$N$113,MATCH(4,$P$18:$P$113,0)),"") -> Control IgG | C21: Reference | E21: Control IgG | G21: =IF(OR(C21="Ligand",C21="Reference",C21="Analyte"),IF(E21="",0,SUMIF(Proteins!$A$5:$A$40,E21,Proteins!$C$5:$C$40))+IF(F21="",0,SUMIF(Proteins!$A$5:$A$40,F21,Proteins!$C$5:$C$40)),"") -> 150000 | I21: =IFERROR(IF(INDEX($Q$18:$Q$113,MATCH(4,$P$18:$P$113,0))-1=INDEX($M$18:$M$113,MATCH(4,$P$18:$P$113,0)),MID("ABCDEFGH",INDEX($M$18:$M$113,MATCH(4,$P$18:$P$113,0)),1),MID("ABCDEFGH",INDEX($M$18:$M$113,MATCH(4,$P$18:$P$113,0)),1)&"-"&MID("ABCDEFGH",INDEX($Q$18:$Q$113,MATCH(4,$P$18:$P$113,0))-1,1)),"") -> A-H | J21: =IF(C21="","",IF(OR(C21="Ligand",C21="Analyte"),C21&" "&COUNTIFS($C$18:C21,C21),C21)) -> Reference | K21: =IFERROR(INDEX($Q$18:$Q$113,MATCH(4,$P$18:$P$113,0))-INDEX($M$18:$M$113,MATCH(4,$P$18:$P$113,0)),"") -> 8 | L21: 1 | M21: 4 | N21: =IF(Setup!B8="","",Setup!B8) -> Buffer | O21: =IF(N21="",0,IF(AND(L21=L20,N21=N20),0,1)) -> 0 | P21: =P20+O21 -> 1 | Q21: =IF(L22<>L21,9,IF(O22=1,M22,Q22)) -> 9
A22: =IFERROR(INDEX($L$18:$L$113,MATCH(5,$P$18:$P$113,0)),"") -> 5 | B22: =IFERROR(INDEX($N$18:$N$113,MATCH(5,$P$18:$P$113,0)),"") -> Buffer | C22: Buffer | G22: =IF(OR(C22="Ligand",C22="Reference",C22="Analyte"),IF(E22="",0,SUMIF(Proteins!$A$5:$A$40,E22,Proteins!$C$5:$C$40))+IF(F22="",0,SUMIF(Proteins!$A$5:$A$40,F22,Proteins!$C$5:$C$40)),"") | I22: =IFERROR(IF(INDEX($Q$18:$Q$113,MATCH(5,$P$18:$P$113,0))-1=INDEX($M$18:$M$113,MATCH(5,$P$18:$P$113,0)),MID("ABCDEFGH",INDEX($M$18:$M$113,MATCH(5,$P$18:$P$113,0)),1),MID("ABCDEFGH",INDEX($M$18:$M$113,MATCH(5,$P$18:$P$113,0)),1)&"-"&MID("ABCDEFGH",INDEX($Q$18:$Q$113,MATCH(5,$P$18:$P$113,0))-1,1)),"") -> A-H | J22: =IF(C22="","",IF(OR(C22="Ligand",C22="Analyte"),C22&" "&COUNTIFS($C$18:C22,C22),C22)) -> Buffer | K22: =IFERROR(INDEX($Q$18:$Q$113,MATCH(5,$P$18:$P$113,0))-INDEX($M$18:$M$113,MATCH(5,$P$18:$P$113,0)),"") -> 8 | L22: 1 | M22: 5 | N22: =IF(Setup!B9="","",Setup!B9) -> Buffer | O22: =IF(N22="",0,IF(AND(L22=L21,N22=N21),0,1)) -> 0 | P22: =P21+O22 -> 1 | Q22: =IF(L23<>L22,9,IF(O23=1,M23,Q23)) -> 9
A23: =IFERROR(INDEX($L$18:$L$113,MATCH(6,$P$18:$P$113,0)),"") -> 6 | B23: =IFERROR(INDEX($N$18:$N$113,MATCH(6,$P$18:$P$113,0)),"") -> Buffer | C23: Buffer | G23: =IF(OR(C23="Ligand",C23="Reference",C23="Analyte"),IF(E23="",0,SUMIF(Proteins!$A$5:$A$40,E23,Proteins!$C$5:$C$40))+IF(F23="",0,SUMIF(Proteins!$A$5:$A$40,F23,Proteins!$C$5:$C$40)),"") | I23: =IFERROR(IF(INDEX($Q$18:$Q$113,MATCH(6,$P$18:$P$113,0))-1=INDEX($M$18:$M$113,MATCH(6,$P$18:$P$113,0)),MID("ABCDEFGH",INDEX($M$18:$M$113,MATCH(6,$P$18:$P$113,0)),1),MID("ABCDEFGH",INDEX($M$18:$M$113,MATCH(6,$P$18:$P$113,0)),1)&"-"&MID("ABCDEFGH",INDEX($Q$18:$Q$113,MATCH(6,$P$18:$P$113,0))-1,1)),"") -> A-H | J23: =IF(C23="","",IF(OR(C23="Ligand",C23="Analyte"),C23&" "&COUNTIFS($C$18:C23,C23),C23)) -> Buffer | K23: =IFERROR(INDEX($Q$18:$Q$113,MATCH(6,$P$18:$P$113,0))-INDEX($M$18:$M$113,MATCH(6,$P$18:$P$113,0)),"") -> 8 | L23: 1 | M23: 6 | N23: =IF(Setup!B10="","",Setup!B10) -> Buffer | O23: =IF(N23="",0,IF(AND(L23=L22,N23=N22),0,1)) -> 0 | P23: =P22+O23 -> 1 | Q23: =IF(L24<>L23,9,IF(O24=1,M24,Q24)) -> 9
A24: =IFERROR(INDEX($L$18:$L$113,MATCH(7,$P$18:$P$113,0)),"") -> 7 | B24: =IFERROR(INDEX($N$18:$N$113,MATCH(7,$P$18:$P$113,0)),"") -> Buffer | C24: Buffer | G24: =IF(OR(C24="Ligand",C24="Reference",C24="Analyte"),IF(E24="",0,SUMIF(Proteins!$A$5:$A$40,E24,Proteins!$C$5:$C$40))+IF(F24="",0,SUMIF(Proteins!$A$5:$A$40,F24,Proteins!$C$5:$C$40)),"") | I24: =IFERROR(IF(INDEX($Q$18:$Q$113,MATCH(7,$P$18:$P$113,0))-1=INDEX($M$18:$M$113,MATCH(7,$P$18:$P$113,0)),MID("ABCDEFGH",INDEX($M$18:$M$113,MATCH(7,$P$18:$P$113,0)),1),MID("ABCDEFGH",INDEX($M$18:$M$113,MATCH(7,$P$18:$P$113,0)),1)&"-"&MID("ABCDEFGH",INDEX($Q$18:$Q$113,MATCH(7,$P$18:$P$113,0))-1,1)),"") -> A-H | J24: =IF(C24="","",IF(OR(C24="Ligand",C24="Analyte"),C24&" "&COUNTIFS($C$18:C24,C24),C24)) -> Buffer | K24: =IFERROR(INDEX($Q$18:$Q$113,MATCH(7,$P$18:$P$113,0))-INDEX($M$18:$M$113,MATCH(7,$P$18:$P$113,0)),"") -> 8 | L24: 1 | M24: 7 | N24: =IF(Setup!B11="","",Setup!B11) -> Buffer | O24: =IF(N24="",0,IF(AND(L24=L23,N24=N23),0,1)) -> 0 | P24: =P23+O24 -> 1 | Q24: =IF(L25<>L24,9,IF(O25=1,M25,Q25)) -> 9
A25: =IFERROR(INDEX($L$18:$L$113,MATCH(8,$P$18:$P$113,0)),"") -> 8 | B25: =IFERROR(INDEX($N$18:$N$113,MATCH(8,$P$18:$P$113,0)),"") -> Analyte X | C25: Analyte | D25: Analyte X | E25: Analyte X | G25: =IF(OR(C25="Ligand",C25="Reference",C25="Analyte"),IF(E25="",0,SUMIF(Proteins!$A$5:$A$40,E25,Proteins!$C$5:$C$40))+IF(F25="",0,SUMIF(Proteins!$A$5:$A$40,F25,Proteins!$C$5:$C$40)),"") -> 21000 | I25: =IFERROR(IF(INDEX($Q$18:$Q$113,MATCH(8,$P$18:$P$113,0))-1=INDEX($M$18:$M$113,MATCH(8,$P$18:$P$113,0)),MID("ABCDEFGH",INDEX($M$18:$M$113,MATCH(8,$P$18:$P$113,0)),1),MID("ABCDEFGH",INDEX($M$18:$M$113,MATCH(8,$P$18:$P$113,0)),1)&"-"&MID("ABCDEFGH",INDEX($Q$18:$Q$113,MATCH(8,$P$18:$P$113,0))-1,1)),"") -> A-H | J25: =IF(C25="","",IF(OR(C25="Ligand",C25="Analyte"),C25&" "&COUNTIFS($C$18:C25,C25),C25)) -> Analyte 1 | K25: =IFERROR(INDEX($Q$18:$Q$113,MATCH(8,$P$18:$P$113,0))-INDEX($M$18:$M$113,MATCH(8,$P$18:$P$113,0)),"") -> 8 | L25: 1 | M25: 8 | N25: =IF(Setup!B12="","",Setup!B12) -> Buffer | O25: =IF(N25="",0,IF(AND(L25=L24,N25=N24),0,1)) -> 0 | P25: =P24+O25 -> 1 | Q25: =IF(L26<>L25,9,IF(O26=1,M26,Q26)) -> 9
A26: =IFERROR(INDEX($L$18:$L$113,MATCH(9,$P$18:$P$113,0)),"") -> 9 | B26: =IFERROR(INDEX($N$18:$N$113,MATCH(9,$P$18:$P$113,0)),"") -> Analyte Y | C26: Analyte | D26: Analyte Y | E26: Analyte Y | G26: =IF(OR(C26="Ligand",C26="Reference",C26="Analyte"),IF(E26="",0,SUMIF(Proteins!$A$5:$A$40,E26,Proteins!$C$5:$C$40))+IF(F26="",0,SUMIF(Proteins!$A$5:$A$40,F26,Proteins!$C$5:$C$40)),"") -> 22000 | I26: =IFERROR(IF(INDEX($Q$18:$Q$113,MATCH(9,$P$18:$P$113,0))-1=INDEX($M$18:$M$113,MATCH(9,$P$18:$P$113,0)),MID("ABCDEFGH",INDEX($M$18:$M$113,MATCH(9,$P$18:$P$113,0)),1),MID("ABCDEFGH",INDEX($M$18:$M$113,MATCH(9,$P$18:$P$113,0)),1)&"-"&MID("ABCDEFGH",INDEX($Q$18:$Q$113,MATCH(9,$P$18:$P$113,0))-1,1)),"") -> A-H | J26: =IF(C26="","",IF(OR(C26="Ligand",C26="Analyte"),C26&" "&COUNTIFS($C$18:C26,C26),C26)) -> Analyte 2 | K26: =IFERROR(INDEX($Q$18:$Q$113,MATCH(9,$P$18:$P$113,0))-INDEX($M$18:$M$113,MATCH(9,$P$18:$P$113,0)),"") -> 8 | L26: 2 | M26: 1 | N26: =IF(Setup!C5="","",Setup!C5) -> Binder A | O26: =IF(N26="",0,IF(AND(L26=L25,N26=N25),0,1)) -> 1 | P26: =P25+O26 -> 2 | Q26: =IF(L27<>L26,9,IF(O27=1,M27,Q27)) -> 9
A27: =IFERROR(INDEX($L$18:$L$113,MATCH(10,$P$18:$P$113,0)),"") -> 10 | B27: =IFERROR(INDEX($N$18:$N$113,MATCH(10,$P$18:$P$113,0)),"") -> Analyte Z | C27: Analyte | D27: Analyte Z | E27: Analyte Z | G27: =IF(OR(C27="Ligand",C27="Reference",C27="Analyte"),IF(E27="",0,SUMIF(Proteins!$A$5:$A$40,E27,Proteins!$C$5:$C$40))+IF(F27="",0,SUMIF(Proteins!$A$5:$A$40,F27,Proteins!$C$5:$C$40)),"") -> 25000 | I27: =IFERROR(IF(INDEX($Q$18:$Q$113,MATCH(10,$P$18:$P$113,0))-1=INDEX($M$18:$M$113,MATCH(10,$P$18:$P$113,0)),MID("ABCDEFGH",INDEX($M$18:$M$113,MATCH(10,$P$18:$P$113,0)),1),MID("ABCDEFGH",INDEX($M$18:$M$113,MATCH(10,$P$18:$P$113,0)),1)&"-"&MID("ABCDEFGH",INDEX($Q$18:$Q$113,MATCH(10,$P$18:$P$113,0))-1,1)),"") -> A-H | J27: =IF(C27="","",IF(OR(C27="Ligand",C27="Analyte"),C27&" "&COUNTIFS($C$18:C27,C27),C27)) -> Analyte 3 | K27: =IFERROR(INDEX($Q$18:$Q$113,MATCH(10,$P$18:$P$113,0))-INDEX($M$18:$M$113,MATCH(10,$P$18:$P$113,0)),"") -> 8 | L27: 2 | M27: 2 | N27: =IF(Setup!C6="","",Setup!C6) -> Binder A | O27: =IF(N27="",0,IF(AND(L27=L26,N27=N26),0,1)) -> 0 | P27: =P26+O27 -> 2 | Q27: =IF(L28<>L27,9,IF(O28=1,M28,Q28)) -> 9
A28: =IFERROR(INDEX($L$18:$L$113,MATCH(11,$P$18:$P$113,0)),"") -> 11 | B28: =IFERROR(INDEX($N$18:$N$113,MATCH(11,$P$18:$P$113,0)),"") -> 10 mM Glycine pH 2.7 | C28: Regeneration | G28: =IF(OR(C28="Ligand",C28="Reference",C28="Analyte"),IF(E28="",0,SUMIF(Proteins!$A$5:$A$40,E28,Proteins!$C$5:$C$40))+IF(F28="",0,SUMIF(Proteins!$A$5:$A$40,F28,Proteins!$C$5:$C$40)),"") | I28: =IFERROR(IF(INDEX($Q$18:$Q$113,MATCH(11,$P$18:$P$113,0))-1=INDEX($M$18:$M$113,MATCH(11,$P$18:$P$113,0)),MID("ABCDEFGH",INDEX($M$18:$M$113,MATCH(11,$P$18:$P$113,0)),1),MID("ABCDEFGH",INDEX($M$18:$M$113,MATCH(11,$P$18:$P$113,0)),1)&"-"&MID("ABCDEFGH",INDEX($Q$18:$Q$113,MATCH(11,$P$18:$P$113,0))-1,1)),"") -> A-H | J28: =IF(C28="","",IF(OR(C28="Ligand",C28="Analyte"),C28&" "&COUNTIFS($C$18:C28,C28),C28)) -> Regeneration | K28: =IFERROR(INDEX($Q$18:$Q$113,MATCH(11,$P$18:$P$113,0))-INDEX($M$18:$M$113,MATCH(11,$P$18:$P$113,0)),"") -> 8 | L28: 2 | M28: 3 | N28: =IF(Setup!C7="","",Setup!C7) -> Binder A | O28: =IF(N28="",0,IF(AND(L28=L27,N28=N27),0,1)) -> 0 | P28: =P27+O28 -> 2 | Q28: =IF(L29<>L28,9,IF(O29=1,M29,Q29)) -> 9
A29: =IFERROR(INDEX($L$18:$L$113,MATCH(12,$P$18:$P$113,0)),"") -> 12 | B29: =IFERROR(INDEX($N$18:$N$113,MATCH(12,$P$18:$P$113,0)),"") -> Buffer | C29: Buffer | G29: =IF(OR(C29="Ligand",C29="Reference",C29="Analyte"),IF(E29="",0,SUMIF(Proteins!$A$5:$A$40,E29,Proteins!$C$5:$C$40))+IF(F29="",0,SUMIF(Proteins!$A$5:$A$40,F29,Proteins!$C$5:$C$40)),"") | I29: =IFERROR(IF(INDEX($Q$18:$Q$113,MATCH(12,$P$18:$P$113,0))-1=INDEX($M$18:$M$113,MATCH(12,$P$18:$P$113,0)),MID("ABCDEFGH",INDEX($M$18:$M$113,MATCH(12,$P$18:$P$113,0)),1),MID("ABCDEFGH",INDEX($M$18:$M$113,MATCH(12,$P$18:$P$113,0)),1)&"-"&MID("ABCDEFGH",INDEX($Q$18:$Q$113,MATCH(12,$P$18:$P$113,0))-1,1)),"") -> A-H | J29: =IF(C29="","",IF(OR(C29="Ligand",C29="Analyte"),C29&" "&COUNTIFS($C$18:C29,C29),C29)) -> Buffer | K29: =IFERROR(INDEX($Q$18:$Q$113,MATCH(12,$P$18:$P$113,0))-INDEX($M$18:$M$113,MATCH(12,$P$18:$P$113,0)),"") -> 8 | L29: 2 | M29: 4 | N29: =IF(Setup!C8="","",Setup!C8) -> Binder A | O29: =IF(N29="",0,IF(AND(L29=L28,N29=N28),0,1)) -> 0 | P29: =P28+O29 -> 2 | Q29: =IF(L30<>L29,9,IF(O30=1,M30,Q30)) -> 9
A30: =IFERROR(INDEX($L$18:$L$113,MATCH(13,$P$18:$P$113,0)),"") | B30: =IFERROR(INDEX($N$18:$N$113,MATCH(13,$P$18:$P$113,0)),"") | G30: =IF(OR(C30="Ligand",C30="Reference",C30="Analyte"),IF(E30="",0,SUMIF(Proteins!$A$5:$A$40,E30,Proteins!$C$5:$C$40))+IF(F30="",0,SUMIF(Proteins!$A$5:$A$40,F30,Proteins!$C$5:$C$40)),"") | I30: =IFERROR(IF(INDEX($Q$18:$Q$113,MATCH(13,$P$18:$P$113,0))-1=INDEX($M$18:$M$113,MATCH(13,$P$18:$P$113,0)),MID("ABCDEFGH",INDEX($M$18:$M$113,MATCH(13,$P$18:$P$113,0)),1),MID("ABCDEFGH",INDEX($M$18:$M$113,MATCH(13,$P$18:$P$113,0)),1)&"-"&MID("ABCDEFGH",INDEX($Q$18:$Q$113,MATCH(13,$P$18:$P$113,0))-1,1)),"") | J30: =IF(C30="","",IF(OR(C30="Ligand",C30="Analyte"),C30&" "&COUNTIFS($C$18:C30,C30),C30)) | K30: =IFERROR(INDEX($Q$18:$Q$113,MATCH(13,$P$18:$P$113,0))-INDEX($M$18:$M$113,MATCH(13,$P$18:$P$113,0)),"") | L30: 2 | M30: 5 | N30: =IF(Setup!C9="","",Setup!C9) -> Binder A | O30: =IF(N30="",0,IF(AND(L30=L29,N30=N29),0,1)) -> 0 | P30: =P29+O30 -> 2 | Q30: =IF(L31<>L30,9,IF(O31=1,M31,Q31)) -> 9
A31: =IFERROR(INDEX($L$18:$L$113,MATCH(14,$P$18:$P$113,0)),"") | B31: =IFERROR(INDEX($N$18:$N$113,MATCH(14,$P$18:$P$113,0)),"") | G31: =IF(OR(C31="Ligand",C31="Reference",C31="Analyte"),IF(E31="",0,SUMIF(Proteins!$A$5:$A$40,E31,Proteins!$C$5:$C$40))+IF(F31="",0,SUMIF(Proteins!$A$5:$A$40,F31,Proteins!$C$5:$C$40)),"") | I31: =IFERROR(IF(INDEX($Q$18:$Q$113,MATCH(14,$P$18:$P$113,0))-1=INDEX($M$18:$M$113,MATCH(14,$P$18:$P$113,0)),MID("ABCDEFGH",INDEX($M$18:$M$113,MATCH(14,$P$18:$P$113,0)),1),MID("ABCDEFGH",INDEX($M$18:$M$113,MATCH(14,$P$18:$P$113,0)),1)&"-"&MID("ABCDEFGH",INDEX($Q$18:$Q$113,MATCH(14,$P$18:$P$113,0))-1,1)),"") | J31: =IF(C31="","",IF(OR(C31="Ligand",C31="Analyte"),C31&" "&COUNTIFS($C$18:C31,C31),C31)) | K31: =IFERROR(INDEX($Q$18:$Q$113,MATCH(14,$P$18:$P$113,0))-INDEX($M$18:$M$113,MATCH(14,$P$18:$P$113,0)),"") | L31: 2 | M31: 6 | N31: =IF(Setup!C10="","",Setup!C10) -> Binder A | O31: =IF(N31="",0,IF(AND(L31=L30,N31=N30),0,1)) -> 0 | P31: =P30+O31 -> 2 | Q31: =IF(L32<>L31,9,IF(O32=1,M32,Q32)) -> 9
A32: =IFERROR(INDEX($L$18:$L$113,MATCH(15,$P$18:$P$113,0)),"") | B32: =IFERROR(INDEX($N$18:$N$113,MATCH(15,$P$18:$P$113,0)),"") | G32: =IF(OR(C32="Ligand",C32="Reference",C32="Analyte"),IF(E32="",0,SUMIF(Proteins!$A$5:$A$40,E32,Proteins!$C$5:$C$40))+IF(F32="",0,SUMIF(Proteins!$A$5:$A$40,F32,Proteins!$C$5:$C$40)),"") | I32: =IFERROR(IF(INDEX($Q$18:$Q$113,MATCH(15,$P$18:$P$113,0))-1=INDEX($M$18:$M$113,MATCH(15,$P$18:$P$113,0)),MID("ABCDEFGH",INDEX($M$18:$M$113,MATCH(15,$P$18:$P$113,0)),1),MID("ABCDEFGH",INDEX($M$18:$M$113,MATCH(15,$P$18:$P$113,0)),1)&"-"&MID("ABCDEFGH",INDEX($Q$18:$Q$113,MATCH(15,$P$18:$P$113,0))-1,1)),"") | J32: =IF(C32="","",IF(OR(C32="Ligand",C32="Analyte"),C32&" "&COUNTIFS($C$18:C32,C32),C32)) | K32: =IFERROR(INDEX($Q$18:$Q$113,MATCH(15,$P$18:$P$113,0))-INDEX($M$18:$M$113,MATCH(15,$P$18:$P$113,0)),"") | L32: 2 | M32: 7 | N32: =IF(Setup!C11="","",Setup!C11) -> Binder A | O32: =IF(N32="",0,IF(AND(L32=L31,N32=N31),0,1)) -> 0 | P32: =P31+O32 -> 2 | Q32: =IF(L33<>L32,9,IF(O33=1,M33,Q33)) -> 9
A33: =IFERROR(INDEX($L$18:$L$113,MATCH(16,$P$18:$P$113,0)),"") | B33: =IFERROR(INDEX($N$18:$N$113,MATCH(16,$P$18:$P$113,0)),"") | G33: =IF(OR(C33="Ligand",C33="Reference",C33="Analyte"),IF(E33="",0,SUMIF(Proteins!$A$5:$A$40,E33,Proteins!$C$5:$C$40))+IF(F33="",0,SUMIF(Proteins!$A$5:$A$40,F33,Proteins!$C$5:$C$40)),"") | I33: =IFERROR(IF(INDEX($Q$18:$Q$113,MATCH(16,$P$18:$P$113,0))-1=INDEX($M$18:$M$113,MATCH(16,$P$18:$P$113,0)),MID("ABCDEFGH",INDEX($M$18:$M$113,MATCH(16,$P$18:$P$113,0)),1),MID("ABCDEFGH",INDEX($M$18:$M$113,MATCH(16,$P$18:$P$113,0)),1)&"-"&MID("ABCDEFGH",INDEX($Q$18:$Q$113,MATCH(16,$P$18:$P$113,0))-1,1)),"") | J33: =IF(C33="","",IF(OR(C33="Ligand",C33="Analyte"),C33&" "&COUNTIFS($C$18:C33,C33),C33)) | K33: =IFERROR(INDEX($Q$18:$Q$113,MATCH(16,$P$18:$P$113,0))-INDEX($M$18:$M$113,MATCH(16,$P$18:$P$113,0)),"") | L33: 2 | M33: 8 | N33: =IF(Setup!C12="","",Setup!C12) -> Binder A | O33: =IF(N33="",0,IF(AND(L33=L32,N33=N32),0,1)) -> 0 | P33: =P32+O33 -> 2 | Q33: =IF(L34<>L33,9,IF(O34=1,M34,Q34)) -> 9
A34: =IFERROR(INDEX($L$18:$L$113,MATCH(17,$P$18:$P$113,0)),"") | B34: =IFERROR(INDEX($N$18:$N$113,MATCH(17,$P$18:$P$113,0)),"") | G34: =IF(OR(C34="Ligand",C34="Reference",C34="Analyte"),IF(E34="",0,SUMIF(Proteins!$A$5:$A$40,E34,Proteins!$C$5:$C$40))+IF(F34="",0,SUMIF(Proteins!$A$5:$A$40,F34,Proteins!$C$5:$C$40)),"") | I34: =IFERROR(IF(INDEX($Q$18:$Q$113,MATCH(17,$P$18:$P$113,0))-1=INDEX($M$18:$M$113,MATCH(17,$P$18:$P$113,0)),MID("ABCDEFGH",INDEX($M$18:$M$113,MATCH(17,$P$18:$P$113,0)),1),MID("ABCDEFGH",INDEX($M$18:$M$113,MATCH(17,$P$18:$P$113,0)),1)&"-"&MID("ABCDEFGH",INDEX($Q$18:$Q$113,MATCH(17,$P$18:$P$113,0))-1,1)),"") | J34: =IF(C34="","",IF(OR(C34="Ligand",C34="Analyte"),C34&" "&COUNTIFS($C$18:C34,C34),C34)) | K34: =IFERROR(INDEX($Q$18:$Q$113,MATCH(17,$P$18:$P$113,0))-INDEX($M$18:$M$113,MATCH(17,$P$18:$P$113,0)),"") | L34: 3 | M34: 1 | N34: =IF(Setup!D5="","",Setup!D5) -> Binder B | O34: =IF(N34="",0,IF(AND(L34=L33,N34=N33),0,1)) -> 1 | P34: =P33+O34 -> 3 | Q34: =IF(L35<>L34,9,IF(O35=1,M35,Q35)) -> 9
A35: =IFERROR(INDEX($L$18:$L$113,MATCH(18,$P$18:$P$113,0)),"") | B35: =IFERROR(INDEX($N$18:$N$113,MATCH(18,$P$18:$P$113,0)),"") | G35: =IF(OR(C35="Ligand",C35="Reference",C35="Analyte"),IF(E35="",0,SUMIF(Proteins!$A$5:$A$40,E35,Proteins!$C$5:$C$40))+IF(F35="",0,SUMIF(Proteins!$A$5:$A$40,F35,Proteins!$C$5:$C$40)),"") | I35: =IFERROR(IF(INDEX($Q$18:$Q$113,MATCH(18,$P$18:$P$113,0))-1=INDEX($M$18:$M$113,MATCH(18,$P$18:$P$113,0)),MID("ABCDEFGH",INDEX($M$18:$M$113,MATCH(18,$P$18:$P$113,0)),1),MID("ABCDEFGH",INDEX($M$18:$M$113,MATCH(18,$P$18:$P$113,0)),1)&"-"&MID("ABCDEFGH",INDEX($Q$18:$Q$113,MATCH(18,$P$18:$P$113,0))-1,1)),"") | J35: =IF(C35="","",IF(OR(C35="Ligand",C35="Analyte"),C35&" "&COUNTIFS($C$18:C35,C35),C35)) | K35: =IFERROR(INDEX($Q$18:$Q$113,MATCH(18,$P$18:$P$113,0))-INDEX($M$18:$M$113,MATCH(18,$P$18:$P$113,0)),"") | L35: 3 | M35: 2 | N35: =IF(Setup!D6="","",Setup!D6) -> Binder B | O35: =IF(N35="",0,IF(AND(L35=L34,N35=N34),0,1)) -> 0 | P35: =P34+O35 -> 3 | Q35: =IF(L36<>L35,9,IF(O36=1,M36,Q36)) -> 9
L36: 3 | M36: 3 | N36: =IF(Setup!D7="","",Setup!D7) -> Binder B | O36: =IF(N36="",0,IF(AND(L36=L35,N36=N35),0,1)) -> 0 | P36: =P35+O36 -> 3 | Q36: =IF(L37<>L36,9,IF(O37=1,M37,Q37)) -> 9
L37: 3 | M37: 4 | N37: =IF(Setup!D8="","",Setup!D8) -> Binder B | O37: =IF(N37="",0,IF(AND(L37=L36,N37=N36),0,1)) -> 0 | P37: =P36+O37 -> 3 | Q37: =IF(L38<>L37,9,IF(O38=1,M38,Q38)) -> 9
L38: 3 | M38: 5 | N38: =IF(Setup!D9="","",Setup!D9) -> Binder B | O38: =IF(N38="",0,IF(AND(L38=L37,N38=N37),0,1)) -> 0 | P38: =P37+O38 -> 3 | Q38: =IF(L39<>L38,9,IF(O39=1,M39,Q39)) -> 9
L39: 3 | M39: 6 | N39: =IF(Setup!D10="","",Setup!D10) -> Binder B | O39: =IF(N39="",0,IF(AND(L39=L38,N39=N38),0,1)) -> 0 | P39: =P38+O39 -> 3 | Q39: =IF(L40<>L39,9,IF(O40=1,M40,Q40)) -> 9
L40: 3 | M40: 7 | N40: =IF(Setup!D11="","",Setup!D11) -> Binder B | O40: =IF(N40="",0,IF(AND(L40=L39,N40=N39),0,1)) -> 0 | P40: =P39+O40 -> 3 | Q40: =IF(L41<>L40,9,IF(O41=1,M41,Q41)) -> 9
L41: 3 | M41: 8 | N41: =IF(Setup!D12="","",Setup!D12) -> Binder B | O41: =IF(N41="",0,IF(AND(L41=L40,N41=N40),0,1)) -> 0 | P41: =P40+O41 -> 3 | Q41: =IF(L42<>L41,9,IF(O42=1,M42,Q42)) -> 9
L42: 4 | M42: 1 | N42: =IF(Setup!E5="","",Setup!E5) -> Control IgG | O42: =IF(N42="",0,IF(AND(L42=L41,N42=N41),0,1)) -> 1 | P42: =P41+O42 -> 4 | Q42: =IF(L43<>L42,9,IF(O43=1,M43,Q43)) -> 9
...

Sheet Setup
A1: Setup | C1: Yellow cells are inputs. White cells are formulas or labels: do not overwrite them. The bli2prism sheet reads this sheet, so edit values but do not move cells.
B2: [Plate map] | D2: Immobilized proteins (concentration: R9) are the Ligand and Reference columns. Roles are set on the bli2prism tab (Role column). | N2: [Dilution series]
A3: Role | B3: =IFERROR(IF(INDEX(bli2prism!$J$18:$J$35,MATCH(1,bli2prism!$A$18:$A$35,0))="","(set role)",INDEX(bli2prism!$J$18:$J$35,MATCH(1,bli2prism!$A$18:$A$35,0))&IF(COUNTIFS(bli2prism!$A$18:$A$35,1)-1>0," +"&COUNTIFS(bli2prism!$A$18:$A$35,1)-1&" more","")),"") -> Buffer | C3: =IFERROR(IF(INDEX(bli2prism!$J$18:$J$35,MATCH(2,bli2prism!$A$18:$A$35,0))="","(set role)",INDEX(bli2prism!$J$18:$J$35,MATCH(2,bli2prism!$A$18:$A$35,0))&IF(COUNTIFS(bli2prism!$A$18:$A$35,2)-1>0," +"&COUNTIFS(bli2prism!$A$18:$A$35,2)-1&" more","")),"") -> Ligand 1 | D3: =IFERROR(IF(INDEX(bli2prism!$J$18:$J$35,MATCH(3,bli2prism!$A$18:$A$35,0))="","(set role)",INDEX(bli2prism!$J$18:$J$35,MATCH(3,bli2prism!$A$18:$A$35,0))&IF(COUNTIFS(bli2prism!$A$18:$A$35,3)-1>0," +"&COUNTIFS(bli2prism!$A$18:$A$35,3)-1&" more","")),"") -> Ligand 2 | E3: =IFERROR(IF(INDEX(bli2prism!$J$18:$J$35,MATCH(4,bli2prism!$A$18:$A$35,0))="","(set role)",INDEX(bli2prism!$J$18:$J$35,MATCH(4,bli2prism!$A$18:$A$35,0))&IF(COUNTIFS(bli2prism!$A$18:$A$35,4)-1>0," +"&COUNTIFS(bli2prism!$A$18:$A$35,4)-1&" more","")),"") -> Reference | F3: =IFERROR(IF(INDEX(bli2prism!$J$18:$J$35,MATCH(5,bli2prism!$A$18:$A$35,0))="","(set role)",INDEX(bli2prism!$J$18:$J$35,MATCH(5,bli2prism!$A$18:$A$35,0))&IF(COUNTIFS(bli2prism!$A$18:$A$35,5)-1>0," +"&COUNTIFS(bli2prism!$A$18:$A$35,5)-1&" more","")),"") -> Buffer | G3: =IFERROR(IF(INDEX(bli2prism!$J$18:$J$35,MATCH(6,bli2prism!$A$18:$A$35,0))="","(set role)",INDEX(bli2prism!$J$18:$J$35,MATCH(6,bli2prism!$A$18:$A$35,0))&IF(COUNTIFS(bli2prism!$A$18:$A$35,6)-1>0," +"&COUNTIFS(bli2prism!$A$18:$A$35,6)-1&" more","")),"") -> Buffer | H3: =IFERROR(IF(INDEX(bli2prism!$J$18:$J$35,MATCH(7,bli2prism!$A$18:$A$35,0))="","(set role)",INDEX(bli2prism!$J$18:$J$35,MATCH(7,bli2prism!$A$18:$A$35,0))&IF(COUNTIFS(bli2prism!$A$18:$A$35,7)-1>0," +"&COUNTIFS(bli2prism!$A$18:$A$35,7)-1&" more","")),"") -> Buffer | I3: =IFERROR(IF(INDEX(bli2prism!$J$18:$J$35,MATCH(8,bli2prism!$A$18:$A$35,0))="","(set role)",INDEX(bli2prism!$J$18:$J$35,MATCH(8,bli2prism!$A$18:$A$35,0))&IF(COUNTIFS(bli2prism!$A$18:$A$35,8)-1>0," +"&COUNTIFS(bli2prism!$A$18:$A$35,8)-1&" more","")),"") -> Analyte 1 | J3: =IFERROR(IF(INDEX(bli2prism!$J$18:$J$35,MATCH(9,bli2prism!$A$18:$A$35,0))="","(set role)",INDEX(bli2prism!$J$18:$J$35,MATCH(9,bli2prism!$A$18:$A$35,0))&IF(COUNTIFS(bli2prism!$A$18:$A$35,9)-1>0," +"&COUNTIFS(bli2prism!$A$18:$A$35,9)-1&" more","")),"") -> Analyte 2 | K3: =IFERROR(IF(INDEX(bli2prism!$J$18:$J$35,MATCH(10,bli2prism!$A$18:$A$35,0))="","(set role)",INDEX(bli2prism!$J$18:$J$35,MATCH(10,bli2prism!$A$18:$A$35,0))&IF(COUNTIFS(bli2prism!$A$18:$A$35,10)-1>0," +"&COUNTIFS(bli2prism!$A$18:$A$35,10)-1&" more","")),"") -> Analyte 3 | L3: =IFERROR(IF(INDEX(bli2prism!$J$18:$J$35,MATCH(11,bli2prism!$A$18:$A$35,0))="","(set role)",INDEX(bli2prism!$J$18:$J$35,MATCH(11,bli2prism!$A$18:$A$35,0))&IF(COUNTIFS(bli2prism!$A$18:$A$35,11)-1>0," +"&COUNTIFS(bli2prism!$A$18:$A$35,11)-1&" more","")),"") -> Regeneration | M3: =IFERROR(IF(INDEX(bli2prism!$J$18:$J$35,MATCH(12,bli2prism!$A$18:$A$35,0))="","(set role)",INDEX(bli2prism!$J$18:$J$35,MATCH(12,bli2prism!$A$18:$A$35,0))&IF(COUNTIFS(bli2prism!$A$18:$A$35,12)-1>0," +"&COUNTIFS(bli2prism!$A$18:$A$35,12)-1&" more","")),"") -> Buffer | N3: Starting concentration, dilution factor and final volume are inputs.
A4: Column | B4: 1 | C4: 2 | D4: 3 | E4: 4 | F4: 5 | G4: 6 | H4: 7 | I4: 8 | J4: 9 | K4: 10 | L4: 11 | M4: 12 | N4: [concentration] (M) | O4: [concentration] (nM) | P4: log | Q4: Dilution settings
A5: A | B5: Buffer | C5: Binder A | D5: Binder B | E5: Control IgG | F5: Buffer | G5: Buffer | H5: Buffer | I5: Analyte X | J5: Analyte Y | K5: Analyte Z | L5: 10 mM Glycine pH 2.7 | M5: Buffer | N5: 1e-06 | O5: =N5*10^9 -> 1000 | P5: =LOG(N5) -> -6 | Q5: Dilution Factor | R5: 3
A6: B | B6: Buffer | C6: Binder A | D6: Binder B | E6: Control IgG | F6: Buffer | G6: Buffer | H6: Buffer | I6: Analyte X | J6: Analyte Y | K6: Analyte Z | L6: 10 mM Glycine pH 2.7 | M6: Buffer | N6: =N5/$R$5 -> 3.3333333e-07 | O6: =N6*10^9 -> 333.33333 | P6: =LOG(N6) -> -6.4771213 | Q6: Transfer volume | R6: =R7/(R5-1) -> 100
A7: C | B7: Buffer | C7: Binder A | D7: Binder B | E7: Control IgG | F7: Buffer | G7: Buffer | H7: Buffer | I7: Analyte X | J7: Analyte Y | K7: Analyte Z | L7: 10 mM Glycine pH 2.7 | M7: Buffer | N7: =N6/$R$5 -> 1.1111111e-07 | O7: =N7*10^9 -> 111.11111 | P7: =LOG(N7) -> -6.9542425 | Q7: Final Volume per Well | R7: 200
A8: D | B8: Buffer | C8: Binder A | D8: Binder B | E8: Control IgG | F8: Buffer | G8: Buffer | H8: Buffer | I8: Analyte X | J8: Analyte Y | K8: Analyte Z | L8: 10 mM Glycine pH 2.7 | M8: Buffer | N8: =N7/$R$5 -> 3.7037037e-08 | O8: =N8*10^9 -> 37.037037 | P8: =LOG(N8) -> -7.4313638 | Q8: Final Volume + Transfer Volume | R8: =SUM(R6:R7) -> 300
A9: E | B9: Buffer | C9: Binder A | D9: Binder B | E9: Control IgG | F9: Buffer | G9: Buffer | H9: Buffer | I9: Analyte X | J9: Analyte Y | K9: Analyte Z | L9: 10 mM Glycine pH 2.7 | M9: Buffer | N9: =N8/$R$5 -> 1.2345679e-08 | O9: =N9*10^9 -> 12.345679 | P9: =LOG(N9) -> -7.908485 | Q9: Immobilized ligand concentration (M) | R9: 1e-07
A10: F | B10: Buffer | C10: Binder A | D10: Binder B | E10: Control IgG | F10: Buffer | G10: Buffer | H10: Buffer | I10: Analyte X | J10: Analyte Y | K10: Analyte Z | L10: 10 mM Glycine pH 2.7 | M10: Buffer | N10: =N9/$R$5 -> 4.1152263e-09 | O10: =N10*10^9 -> 4.1152263 | P10: =LOG(N10) -> -8.3856063 | Q10: Ligand volume per sensor row (uL) | R10: 200
A11: G | B11: Buffer | C11: Binder A | D11: Binder B | E11: Control IgG | F11: Buffer | G11: Buffer | H11: Buffer | I11: Analyte X | J11: Analyte Y | K11: Analyte Z | L11: 10 mM Glycine pH 2.7 | M11: Buffer | N11: =N10/$R$5 -> 1.3717421e-09 | O11: =N11*10^9 -> 1.3717421 | P11: =LOG(N11) -> -8.8627275 | Q11: Volume excess factor | R11: 1.2
A12: H | B12: Buffer | C12: Binder A | D12: Binder B | E12: Control IgG | F12: Buffer | G12: Buffer | H12: Buffer | I12: Analyte X | J12: Analyte Y | K12: Analyte Z | L12: 10 mM Glycine pH 2.7 | M12: Buffer | N12: =N11/$R$5 -> 4.5724737e-10 | O12: =N12*10^9 -> 0.45724737 | P12: =LOG(N12) -> -9.3398488
B13: The tool reads plate row A (row 5); the other rows are for your records.
B14: Ligand N = raw files N.xls (1.xls, 2.xls, ...); Analyte N = the Nth trace in each raw file; Reference = the sensor that was subtracted.

Sheet Proteins
A1: Proteins and bench prep | C1: Yellow cells are inputs. White cells are formulas: do not overwrite them. The bli2prism sheet reads protein names (column A) and MWs (column C) in rows 5-40.
A2: Inputs: name, A280, MW and extinction coefficient. Role comes from the bli2prism tab; the desired concentration and total volume follow it (see README: Ligand / Reference use Setup!R9 and the sensor rows, Analyte uses Setup!N5 and R8). To add a protein, copy the last row down.
A4: Protein | B4: A280 | C4: Molecular weight (g/mol) | D4: Extinction Coefficient | E4: Concentration (M) | F4: Concentration (mg/mL) | G4: Moles Needed | H4: Desired Concentration (mol/L) | I4: Total Volume (uL) | J4: Vol Protein (uL) | K4: Vol buffer (ul) | L4: Vol buffer (ul) / 2 | M4: Mass protein needed (ug) | N4: Role (from bli2prism tab)
A5: Binder A | B5: 1.5 | C5: 145000 | D5: 31000 | E5: =B5/D5 -> 4.8387097e-05 | F5: =E5*C5 -> 7.016129 | G5: =H5*I5*10^-6 -> 1.92e-10 | H5: =IF(OR(N5="Analyte",N5="Ligand + Analyte"),Setup!$N$5,IF(OR(N5="Ligand",N5="Reference"),Setup!$R$9,0)) -> 1e-07 | I5: =IF(OR(N5="Analyte",N5="Ligand + Analyte"),Setup!$R$8*Setup!$R$11,IF(OR(N5="Ligand",N5="Reference"),(SUMIFS(bli2prism!$K$18:$K$113,bli2prism!$C$18:$C$113,"Ligand",bli2prism!$E$18:$E$113,$A5)+SUMIFS(bli2prism!$K$18:$K$113,bli2prism!$C$18:$C$113,"Ligand",bli2prism!$F$18:$F$113,$A5)+SUMIFS(bli2prism!$K$18:$K$113,bli2prism!$C$18:$C$113,"Reference",bli2prism!$E$18:$E$113,$A5)+SUMIFS(bli2prism!$K$18:$K$113,bli2prism!$C$18:$C$113,"Reference",bli2prism!$F$18:$F$113,$A5))*Setup!$R$10*Setup!$R$11,0)) -> 1920 | J5: =G5/E5*10^6 -> 3.968 | K5: =I5-J5 -> 1916.032 | L5: =K5/2 -> 958.016 | M5: =F5*J5 -> 27.84 | N5: =IF($A5="","",IF(AND(COUNTIFS(bli2prism!$C$18:$C$113,"Ligand",bli2prism!$E$18:$E$113,$A5)+COUNTIFS(bli2prism!$C$18:$C$113,"Ligand",bli2prism!$F$18:$F$113,$A5)>0,COUNTIFS(bli2prism!$C$18:$C$113,"Analyte",bli2prism!$E$18:$E$113,$A5)+COUNTIFS(bli2prism!$C$18:$C$113,"Analyte",bli2prism!$F$18:$F$113,$A5)>0),"Ligand + Analyte",IF(COUNTIFS(bli2prism!$C$18:$C$113,"Analyte",bli2prism!$E$18:$E$113,$A5)+COUNTIFS(bli2prism!$C$18:$C$113,"Analyte",bli2prism!$F$18:$F$113,$A5)>0,"Analyte",IF(COUNTIFS(bli2prism!$C$18:$C$113,"Ligand",bli2prism!$E$18:$E$113,$A5)+COUNTIFS(bli2prism!$C$18:$C$113,"Ligand",bli2prism!$F$18:$F$113,$A5)>0,"Ligand",IF(COUNTIFS(bli2prism!$C$18:$C$113,"Reference",bli2prism!$E$18:$E$113,$A5)+COUNTIFS(bli2prism!$C$18:$C$113,"Reference",bli2prism!$F$18:$F$113,$A5)>0,"Reference",""))))) -> Ligand
A6: Binder B | B6: 1.2 | C6: 148000 | D6: 29000 | E6: =B6/D6 -> 4.137931e-05 | F6: =E6*C6 -> 6.1241379 | G6: =H6*I6*10^-6 -> 1.92e-10 | H6: =IF(OR(N6="Analyte",N6="Ligand + Analyte"),Setup!$N$5,IF(OR(N6="Ligand",N6="Reference"),Setup!$R$9,0)) -> 1e-07 | I6: =IF(OR(N6="Analyte",N6="Ligand + Analyte"),Setup!$R$8*Setup!$R$11,IF(OR(N6="Ligand",N6="Reference"),(SUMIFS(bli2prism!$K$18:$K$113,bli2prism!$C$18:$C$113,"Ligand",bli2prism!$E$18:$E$113,$A6)+SUMIFS(bli2prism!$K$18:$K$113,bli2prism!$C$18:$C$113,"Ligand",bli2prism!$F$18:$F$113,$A6)+SUMIFS(bli2prism!$K$18:$K$113,bli2prism!$C$18:$C$113,"Reference",bli2prism!$E$18:$E$113,$A6)+SUMIFS(bli2prism!$K$18:$K$113,bli2prism!$C$18:$C$113,"Reference",bli2prism!$F$18:$F$113,$A6))*Setup!$R$10*Setup!$R$11,0)) -> 1920 | J6: =G6/E6*10^6 -> 4.64 | K6: =I6-J6 -> 1915.36 | L6: =K6/2 -> 957.68 | M6: =F6*J6 -> 28.416 | N6: =IF($A6="","",IF(AND(COUNTIFS(bli2prism!$C$18:$C$113,"Ligand",bli2prism!$E$18:$E$113,$A6)+COUNTIFS(bli2prism!$C$18:$C$113,"Ligand",bli2prism!$F$18:$F$113,$A6)>0,COUNTIFS(bli2prism!$C$18:$C$113,"Analyte",bli2prism!$E$18:$E$113,$A6)+COUNTIFS(bli2prism!$C$18:$C$113,"Analyte",bli2prism!$F$18:$F$113,$A6)>0),"Ligand + Analyte",IF(COUNTIFS(bli2prism!$C$18:$C$113,"Analyte",bli2prism!$E$18:$E$113,$A6)+COUNTIFS(bli2prism!$C$18:$C$113,"Analyte",bli2prism!$F$18:$F$113,$A6)>0,"Analyte",IF(COUNTIFS(bli2prism!$C$18:$C$113,"Ligand",bli2prism!$E$18:$E$113,$A6)+COUNTIFS(bli2prism!$C$18:$C$113,"Ligand",bli2prism!$F$18:$F$113,$A6)>0,"Ligand",IF(COUNTIFS(bli2prism!$C$18:$C$113,"Reference",bli2prism!$E$18:$E$113,$A6)+COUNTIFS(bli2prism!$C$18:$C$113,"Reference",bli2prism!$F$18:$F$113,$A6)>0,"Reference",""))))) -> Ligand
A7: Control IgG | B7: 1.4 | C7: 150000 | D7: 210000 | E7: =B7/D7 -> 6.6666667e-06 | F7: =E7*C7 -> 1 | G7: =H7*I7*10^-6 -> 1.92e-10 | H7: =IF(OR(N7="Analyte",N7="Ligand + Analyte"),Setup!$N$5,IF(OR(N7="Ligand",N7="Reference"),Setup!$R$9,0)) -> 1e-07 | I7: =IF(OR(N7="Analyte",N7="Ligand + Analyte"),Setup!$R$8*Setup!$R$11,IF(OR(N7="Ligand",N7="Reference"),(SUMIFS(bli2prism!$K$18:$K$113,bli2prism!$C$18:$C$113,"Ligand",bli2prism!$E$18:$E$113,$A7)+SUMIFS(bli2prism!$K$18:$K$113,bli2prism!$C$18:$C$113,"Ligand",bli2prism!$F$18:$F$113,$A7)+SUMIFS(bli2prism!$K$18:$K$113,bli2prism!$C$18:$C$113,"Reference",bli2prism!$E$18:$E$113,$A7)+SUMIFS(bli2prism!$K$18:$K$113,bli2prism!$C$18:$C$113,"Reference",bli2prism!$F$18:$F$113,$A7))*Setup!$R$10*Setup!$R$11,0)) -> 1920 | J7: =G7/E7*10^6 -> 28.8 | K7: =I7-J7 -> 1891.2 | L7: =K7/2 -> 945.6 | M7: =F7*J7 -> 28.8 | N7: =IF($A7="","",IF(AND(COUNTIFS(bli2prism!$C$18:$C$113,"Ligand",bli2prism!$E$18:$E$113,$A7)+COUNTIFS(bli2prism!$C$18:$C$113,"Ligand",bli2prism!$F$18:$F$113,$A7)>0,COUNTIFS(bli2prism!$C$18:$C$113,"Analyte",bli2prism!$E$18:$E$113,$A7)+COUNTIFS(bli2prism!$C$18:$C$113,"Analyte",bli2prism!$F$18:$F$113,$A7)>0),"Ligand + Analyte",IF(COUNTIFS(bli2prism!$C$18:$C$113,"Analyte",bli2prism!$E$18:$E$113,$A7)+COUNTIFS(bli2prism!$C$18:$C$113,"Analyte",bli2prism!$F$18:$F$113,$A7)>0,"Analyte",IF(COUNTIFS(bli2prism!$C$18:$C$113,"Ligand",bli2prism!$E$18:$E$113,$A7)+COUNTIFS(bli2prism!$C$18:$C$113,"Ligand",bli2prism!$F$18:$F$113,$A7)>0,"Ligand",IF(COUNTIFS(bli2prism!$C$18:$C$113,"Reference",bli2prism!$E$18:$E$113,$A7)+COUNTIFS(bli2prism!$C$18:$C$113,"Reference",bli2prism!$F$18:$F$113,$A7)>0,"Reference",""))))) -> Reference
A8: Analyte X | B8: 0.4 | C8: 21000 | D8: 15000 | E8: =B8/D8 -> 2.6666667e-05 | F8: =E8*C8 -> 0.56 | G8: =H8*I8*10^-6 -> 3.6e-10 | H8: =IF(OR(N8="Analyte",N8="Ligand + Analyte"),Setup!$N$5,IF(OR(N8="Ligand",N8="Reference"),Setup!$R$9,0)) -> 1e-06 | I8: =IF(OR(N8="Analyte",N8="Ligand + Analyte"),Setup!$R$8*Setup!$R$11,IF(OR(N8="Ligand",N8="Reference"),(SUMIFS(bli2prism!$K$18:$K$113,bli2prism!$C$18:$C$113,"Ligand",bli2prism!$E$18:$E$113,$A8)+SUMIFS(bli2prism!$K$18:$K$113,bli2prism!$C$18:$C$113,"Ligand",bli2prism!$F$18:$F$113,$A8)+SUMIFS(bli2prism!$K$18:$K$113,bli2prism!$C$18:$C$113,"Reference",bli2prism!$E$18:$E$113,$A8)+SUMIFS(bli2prism!$K$18:$K$113,bli2prism!$C$18:$C$113,"Reference",bli2prism!$F$18:$F$113,$A8))*Setup!$R$10*Setup!$R$11,0)) -> 360 | J8: =G8/E8*10^6 -> 13.5 | K8: =I8-J8 -> 346.5 | L8: =K8/2 -> 173.25 | M8: =F8*J8 -> 7.56 | N8: =IF($A8="","",IF(AND(COUNTIFS(bli2prism!$C$18:$C$113,"Ligand",bli2prism!$E$18:$E$113,$A8)+COUNTIFS(bli2prism!$C$18:$C$113,"Ligand",bli2prism!$F$18:$F$113,$A8)>0,COUNTIFS(bli2prism!$C$18:$C$113,"Analyte",bli2prism!$E$18:$E$113,$A8)+COUNTIFS(bli2prism!$C$18:$C$113,"Analyte",bli2prism!$F$18:$F$113,$A8)>0),"Ligand + Analyte",IF(COUNTIFS(bli2prism!$C$18:$C$113,"Analyte",bli2prism!$E$18:$E$113,$A8)+COUNTIFS(bli2prism!$C$18:$C$113,"Analyte",bli2prism!$F$18:$F$113,$A8)>0,"Analyte",IF(COUNTIFS(bli2prism!$C$18:$C$113,"Ligand",bli2prism!$E$18:$E$113,$A8)+COUNTIFS(bli2prism!$C$18:$C$113,"Ligand",bli2prism!$F$18:$F$113,$A8)>0,"Ligand",IF(COUNTIFS(bli2prism!$C$18:$C$113,"Reference",bli2prism!$E$18:$E$113,$A8)+COUNTIFS(bli2prism!$C$18:$C$113,"Reference",bli2prism!$F$18:$F$113,$A8)>0,"Reference",""))))) -> Analyte
A9: Analyte Y | B9: 0.55 | C9: 22000 | D9: 26000 | E9: =B9/D9 -> 2.1153846e-05 | F9: =E9*C9 -> 0.46538462 | G9: =H9*I9*10^-6 -> 3.6e-10 | H9: =IF(OR(N9="Analyte",N9="Ligand + Analyte"),Setup!$N$5,IF(OR(N9="Ligand",N9="Reference"),Setup!$R$9,0)) -> 1e-06 | I9: =IF(OR(N9="Analyte",N9="Ligand + Analyte"),Setup!$R$8*Setup!$R$11,IF(OR(N9="Ligand",N9="Reference"),(SUMIFS(bli2prism!$K$18:$K$113,bli2prism!$C$18:$C$113,"Ligand",bli2prism!$E$18:$E$113,$A9)+SUMIFS(bli2prism!$K$18:$K$113,bli2prism!$C$18:$C$113,"Ligand",bli2prism!$F$18:$F$113,$A9)+SUMIFS(bli2prism!$K$18:$K$113,bli2prism!$C$18:$C$113,"Reference",bli2prism!$E$18:$E$113,$A9)+SUMIFS(bli2prism!$K$18:$K$113,bli2prism!$C$18:$C$113,"Reference",bli2prism!$F$18:$F$113,$A9))*Setup!$R$10*Setup!$R$11,0)) -> 360 | J9: =G9/E9*10^6 -> 17.018182 | K9: =I9-J9 -> 342.98182 | L9: =K9/2 -> 171.49091 | M9: =F9*J9 -> 7.92 | N9: =IF($A9="","",IF(AND(COUNTIFS(bli2prism!$C$18:$C$113,"Ligand",bli2prism!$E$18:$E$113,$A9)+COUNTIFS(bli2prism!$C$18:$C$113,"Ligand",bli2prism!$F$18:$F$113,$A9)>0,COUNTIFS(bli2prism!$C$18:$C$113,"Analyte",bli2prism!$E$18:$E$113,$A9)+COUNTIFS(bli2prism!$C$18:$C$113,"Analyte",bli2prism!$F$18:$F$113,$A9)>0),"Ligand + Analyte",IF(COUNTIFS(bli2prism!$C$18:$C$113,"Analyte",bli2prism!$E$18:$E$113,$A9)+COUNTIFS(bli2prism!$C$18:$C$113,"Analyte",bli2prism!$F$18:$F$113,$A9)>0,"Analyte",IF(COUNTIFS(bli2prism!$C$18:$C$113,"Ligand",bli2prism!$E$18:$E$113,$A9)+COUNTIFS(bli2prism!$C$18:$C$113,"Ligand",bli2prism!$F$18:$F$113,$A9)>0,"Ligand",IF(COUNTIFS(bli2prism!$C$18:$C$113,"Reference",bli2prism!$E$18:$E$113,$A9)+COUNTIFS(bli2prism!$C$18:$C$113,"Reference",bli2prism!$F$18:$F$113,$A9)>0,"Reference",""))))) -> Analyte
A10: Analyte Z | B10: 0.6 | C10: 25000 | D10: 23000 | E10: =B10/D10 -> 2.6086957e-05 | F10: =E10*C10 -> 0.65217391 | G10: =H10*I10*10^-6 -> 3.6e-10 | H10: =IF(OR(N10="Analyte",N10="Ligand + Analyte"),Setup!$N$5,IF(OR(N10="Ligand",N10="Reference"),Setup!$R$9,0)) -> 1e-06 | I10: =IF(OR(N10="Analyte",N10="Ligand + Analyte"),Setup!$R$8*Setup!$R$11,IF(OR(N10="Ligand",N10="Reference"),(SUMIFS(bli2prism!$K$18:$K$113,bli2prism!$C$18:$C$113,"Ligand",bli2prism!$E$18:$E$113,$A10)+SUMIFS(bli2prism!$K$18:$K$113,bli2prism!$C$18:$C$113,"Ligand",bli2prism!$F$18:$F$113,$A10)+SUMIFS(bli2prism!$K$18:$K$113,bli2prism!$C$18:$C$113,"Reference",bli2prism!$E$18:$E$113,$A10)+SUMIFS(bli2prism!$K$18:$K$113,bli2prism!$C$18:$C$113,"Reference",bli2prism!$F$18:$F$113,$A10))*Setup!$R$10*Setup!$R$11,0)) -> 360 | J10: =G10/E10*10^6 -> 13.8 | K10: =I10-J10 -> 346.2 | L10: =K10/2 -> 173.1 | M10: =F10*J10 -> 9 | N10: =IF($A10="","",IF(AND(COUNTIFS(bli2prism!$C$18:$C$113,"Ligand",bli2prism!$E$18:$E$113,$A10)+COUNTIFS(bli2prism!$C$18:$C$113,"Ligand",bli2prism!$F$18:$F$113,$A10)>0,COUNTIFS(bli2prism!$C$18:$C$113,"Analyte",bli2prism!$E$18:$E$113,$A10)+COUNTIFS(bli2prism!$C$18:$C$113,"Analyte",bli2prism!$F$18:$F$113,$A10)>0),"Ligand + Analyte",IF(COUNTIFS(bli2prism!$C$18:$C$113,"Analyte",bli2prism!$E$18:$E$113,$A10)+COUNTIFS(bli2prism!$C$18:$C$113,"Analyte",bli2prism!$F$18:$F$113,$A10)>0,"Analyte",IF(COUNTIFS(bli2prism!$C$18:$C$113,"Ligand",bli2prism!$E$18:$E$113,$A10)+COUNTIFS(bli2prism!$C$18:$C$113,"Ligand",bli2prism!$F$18:$F$113,$A10)>0,"Ligand",IF(COUNTIFS(bli2prism!$C$18:$C$113,"Reference",bli2prism!$E$18:$E$113,$A10)+COUNTIFS(bli2prism!$C$18:$C$113,"Reference",bli2prism!$F$18:$F$113,$A10)>0,"Reference",""))))) -> Analyte
